Workbook

Sheet 특이사항
A2: 2023.05 특이사항
A4: (1) 하나은행 KRW 거래내역 질문
B5: 은행 조회 자료 | G5: Weekly Cash Closing Package 자료 발췌 | I5: KPMG 질문 | J5: EQUIS 답변
B6: No | C6: 거래일시 | D6: 적요 | E6: 의뢰인/수취인 | F6: 입금 | G6: Description | H6: Concur Invoice Name (Racquel)
B7: 1 | C7: 2023-02-23 09:48:37 | D7: 삼성화재입금 | E7: 삼성화재해상보험(주 | F7: 736480 | H7: no supporting documents | J7: >>(구)금명에게 지급하여야 함.
B8: 2 | C8: 2023-02-23 10:50:17 | D8: 삼성화재입금 | E8: 삼성화재해상보험(주 | F8: 707420 | H8: no supporting documents | J8: >>(구)금명에게 지급하여야 함.
B9: 3 | C9: 2023-02-23 14:41:15 | D9: 산재반환금 | E9: 근로복지공단 | F9: 476370 | H9: no supporting documents | J9: >>(구)금명에게 지급하여야 함.
B10: 4 | C10: 2023-02-23 14:41:17 | D10: 석면반환금 | E10: 근로복지공단 | F10: 1420 | H10: no supporting documents | J10: >>(구)금명에게 지급하여야 함.
B11: 5 | C11: 2023-02-23 14:41:25 | D11: 임채반환금 | E11: 근로복지공단 | F11: 28580 | H11: no supporting documents | J11: >>(구)금명에게 지급하여야 함.
B12: 6 | C12: 2023-02-28 17:08:22 | D12: 과오납연금 | E12: 국민연금 | F12: 216230 | H12: Overpayment | J12: >>(구)금명에게 지급하여야 함.
B13: 7 | C13: 2023-03-13 17:07:55 | D13: 과오납연금 | E13: 국민연금 | F13: 440450 | J13: >>(구)금명에게 지급하여야 함.
B14: 8 | C14: 2023-03-14 16:15:19 | D14: 한전남전주지사 | E14: 한국전력공사 | F14: 592060 | J14: >>(구)금명에게 지급하여야 함.
A16: (2) 하나은행 USD 거래내역 질문
B17: 은행 조회 자료 | G17: Weekly Cash Closing Package 자료 발췌 | I17: KPMG 질문 | J17: EQUIS 답변
B18: No | C18: 거래일시 | D18: 적요 | E18: 통화 | F18: 입금 | G18: Description | H18: Concur Invoice Name (Racquel)
B19: 1 | C19: 2023-01-13 14:51:59 | D19: 에퀴스에너지코리아2유한회사 | E19: USD | F19: 5360000 | G19: 에퀴스에너지코리아2유한회사 | H19: no supporting documents | I19: 계약서 요청_기간, 이자율 확인 필요 | J19: 계약서 수령, 14%, 원화금액으로 인식
A21: (3) 신협 거래내역 질문
B22: 은행 조회 자료 | G22: Weekly Cash Closing Package 자료 발췌 | I22: KPMG 질문 | J22: EQUIS 답변
B23: 순번 | C23: 거래일자 | D23: 출금금액 | E23: 입금금액 | F23: 거래기록사항 | G23: Description | H23: Concur Invoice Name (Racquel)
B24: 1 | C24: 2023-03-30 | D24: 0 | E24: 63040 | F24: 건강보험환급 | G24: 전자금융 | H24: no supporting documents | J24: >>(구)금명에게 지급하여야 함.
B25: 2 | C25: 2023-03-30 | D25: 0 | E25: 11200 | F25: 장기요양환급 | G25: 전자금융 | H25: no supporting documents | J25: >>(구)금명에게 지급하여야 함.
B26: 3 | C26: 2023-04-07 | D26: 0 | E26: 358440 | F26: 건강보험환급 | G26: 전자금융 | H26: no supporting documents | J26: >>(구)금명에게 지급하여야 함.
B27: 4 | C27: 2023-04-07 | D27: 0 | E27: 46210 | F27: 장기요양환급 | G27: 전자금융 | H27: no supporting documents | J27: >>(구)금명에게 지급하여야 함.
B28: 5 | C28: 2023-04-20 | D28: 0 | E28: 112840 | F28: 장기요양환급 | G28: 전자금융 | H28: no supporting documents | J28: >>(구)금명에게 지급하여야 함.
B29: 6 | C29: 2023-04-20 | D29: 0 | E29: 881040 | F29: 건강보험환급 | G29: 전자금융 | H29: no supporting documents | J29: >>(구)금명에게 지급하여야 함.
B30: 7 | C30: 2023-05-02 | D30: 8712328 | E30: 0 | F30: 210059099464 | G30: Local office mainten | H30: no supporting documents | I30: 출금사유 및 증빙 요청 | J30: 대출금 계약서 제공해주심
B31: 8 | C31: 2023-05-31 | D31: 9002739 | E31: 0 | F31: 210059099464 | G31: 210059099464 | H31: no supporting documents | I31: 출금사유 및 증빙 요청 | J31: 대출금 계약서 제공해주심
A33: (4) 기타
B34: NO | C34: 내용 | I34: KPMG 질문 | J34: EQUIS 답변
B35: 1 | C35: 통장출금_토지 매매대금 | I35: 통장 출금내역 중 토지 매매대금, 취득세 등은 토지 계정으로 반영 예정입니다. | J35: ok 유선확인
B36: 2 | C36: 통장출금_취득세 납부
B37: 3 | C37: 매입세금계산서_법무사수수료 (등기) | I37: 매입세금계산서중 법무사비용은 토지 취득의 부대비용으로, 매입세액 불공제 하고 토지 계정으로 반영 예정입니다. | J37: ok 유선확인
A39: (5) 매입세금계산서 및 계산서
B40: 구분 | C40: 작성일자 | D40: 상호 | E40: 합계금액 | F40: 공급가액 | G40: 세액 | H40: 품목명 | I40: KPMG 질문 | J40: EQUIS 답변
B41: 세금계산서 | C41: 2023-02-07 | D41: 주식회사 케이티 | E41: 54516 | F41: 49560 | G41: 4956 | H41: 일반전화 (006103335896) | I41: 대금납부_금명? Or 금명건설? | J41: 금명건설이 납부해야 함, 장부반영x / 부가세 수정 필요함
B42: 세금계산서 | C42: 2023-02-07 | D42: 주식회사 케이티 | E42: 39600 | F42: 36000 | G42: 3600 | H42: 인터넷 베이직 (z!67151690062) | I42: 대금납부_금명? Or 금명건설? | J42: 금명건설이 납부해야 함, 장부반영x / 부가세 수정 필요함
B43: 세금계산서 | C43: 2023-02-09 | D43: 한국전력공사 | E43: 334749 | F43: 304317 | G43: 30432 | H43: 전기요금(1228771682) | I43: 대금납부_금명? Or 금명건설? | J43: 금명건설이 납부해야 함, 장부반영x / 부가세 수정 필요함
B44: 세금계산서 | C44: 2023-02-09 | D44: 한국전력공사 | E44: 77123 | F44: 70112 | G44: 7011 | H44: 전기요금(0341826108) | I44: 대금납부_금명? Or 금명건설? | J44: 금명건설이 납부해야 함, 장부반영x / 부가세 수정 필요함
B45: 세금계산서 | C45: 2023-03-09 | D45: 한국전력공사 | E45: 278388 | F45: 253080 | G45: 25308 | H45: 전기요금(1228771682) | I45: 대금납부_금명? Or 금명건설? | J45: 금명건설이 납부해야 함, 장부반영x / 부가세 수정 필요함
B46: 세금계산서 | C46: 2023-05-07 | D46: 주식회사 케이티 | E46: 97572 | F46: 88702 | G46: 8870 | H46: 일반전화 (006102434885) | I46: 대금납부_금명
...

Sheet FS →

Sheet CONTENTS
C2: 46112
D5: Kummyung Ltd.
D6: MONTHLY REPORTING CONTENTS
B11: FINANCIAL STATEMENTS
B12: - | C12: BALANCE SHEET
B13: - | C13: INCOME STATEMENT
B14: - | C14: TRIAL BALANCE
B15: - | C15: JOURNAL ENTRY
B16: - | C16: GENERAL LEDGER
B17: - | C17: GENERAL LEDGER(Up to reported month)
B19: DETAIL FOR BS RECONCILIATION
B20: - | C20: SUMMARY BANK
B21: - | C21: PREPAID TAX
B22: - | C22: Loan receivables
B23: - | C23: Intercompany loans
B24: - | C24: FX - realized / unrealized gains & losses
B25: - | C25: VAT payable
B26: - | C26: GST/VAT receivable
B27: - | C27: CAPITAL

Sheet journal 2025_KPMG
B1: ※ 조회기간 : 2025/01/01 ~ 2025/02/28
A2: 전표월 | B2: 전표번호 | C2: 현재상태 | D2: 전표일자 | E2: 제목 | F2: 기표일 | G2: 이체일 | H2: 계정 | I2: 계정명 | J2: 차변(FC) | K2: 대변(FC) | L2: 통화 | M2: 환율 | N2: 차변(TC) | O2: 대변(TC) | P2: 거래처코드 | R2: 거래처명 | S2: 은행명 | T2: 은행계좌 | U2: 예금주 | V2: 증빙종류 | W2: 적요 | X2: 보조계정 | Y2: 보조계정명 | Z2: 반제여부 | AA2: 반제일자 | AB2: 반제 계정코드 | AC2: 반제-계정명 | AD2: 반제-은행 | AE2: 반제-계좌 | AF2: 반제-예금주 | AG2: 확장코드 | AH2: 확장코드명
A3: =MID(D3,1,6) -> 202501 | B3: 250100001UP | C3: 승인 | D3: 20250102 | E3: (HTX)_공인인증서(은행/보험용) | H3: 5301-00-000 | I3: 은행 수수료 | J3: 4000 | K3: 0 | L3: KRW | M3: 1 | N3: 4000 | P3: 2028114695 | R3: HANA BANK (주)하나은행 | W3: 공인인증서(은행/보험용)_HANA BANK (주)하나은행 | Z3: OFF | AG3: PTI | AH3: 매입세금계산서
A4: =MID(D4,1,6) -> 202501 | B4: 250100001UP | C4: 승인 | D4: 20250102 | E4: (HTX)_공인인증서(은행/보험용) | H4: 2407-00-000 | I4: 부가세대급금 | J4: 400 | K4: 0 | L4: KRW | M4: 1 | N4: 400 | P4: 2028114695 | R4: HANA BANK (주)하나은행 | W4: VAT_공인인증서(은행/보험용)_HANA BANK (주)하나은행 | Z4: OFF | AG4: PTI | AH4: 매입세금계산서
A5: =MID(D5,1,6) -> 202501 | B5: 250100001UP | C5: 승인 | D5: 20250102 | E5: (HTX)_공인인증서(은행/보험용) | H5: 2202-00-001 | I5: 기타미지급금 | J5: 0 | K5: 4400 | L5: KRW | M5: 1 | O5: 4400 | P5: 2028114695 | R5: HANA BANK (주)하나은행 | W5: 공인인증서(은행/보험용)_HANA BANK (주)하나은행 | Z5: OFF | AG5: PTI | AH5: 매입세금계산서
A6: =MID(D6,1,6) -> 202501 | B6: 250100006UP | C6: 승인 | D6: 20250102 | E6: [KR Inv_202412] VJIPYON02_Kummyung_Registration fee for debt to equity_KRW 23487000 | H6: 1112-KR-001 | I6: 현금 - 원 (HANA) | J6: 0 | K6: 23487500 | L6: KRW | M6: 1 | O6: 23487500 | P6: 201-910031-85704 | R6: HANA_Bank 하나은행(85704) | W6: [KR Inv_202412] VJIPYON02_Kummyung_Registration fee for debt to equity_KRW 23487000 | Z6: OFF | AG6: BANK | AH6: 통장
A7: =MID(D7,1,6) -> 202501 | B7: 250100006UP | C7: 승인 | D7: 20250102 | E7: [KR Inv_202412] VJIPYON02_Kummyung_Registration fee for debt to equity_KRW 23487000 | H7: 2202-00-001 | I7: 기타미지급금 | J7: 23487000 | K7: 0 | L7: KRW | M7: 1 | N7: 23487000 | P7: 1048617068 | R7: JIPYONG LLC.법무법인(유한) 지평 | W7: [KR Inv_202412] VJIPYON02_Kummyung_Registration fee for debt to equity_KRW 23487000 | Z7: OFF | AG7: BANK | AH7: 통장
A8: =MID(D8,1,6) -> 202501 | B8: 250100006UP | C8: 승인 | D8: 20250102 | E8: [KR Inv_202412] VJIPYON02_Kummyung_Registration fee for debt to equity_KRW 23487000 | H8: 5301-00-000 | I8: 은행 수수료 | J8: 500 | K8: 0 | L8: KRW | M8: 1 | N8: 500 | P8: 201-910031-85704 | R8: HANA_Bank 하나은행(85704) | W8: Bank charge | Z8: OFF | AG8: BANK | AH8: 통장
A9: =MID(D9,1,6) -> 202501 | B9: 250100007UP | C9: 승인 | D9: 20250102 | E9: [KR Inv_202411] VNEULSA01_Kummyung_Real estate transaction amount_KRW 12000000 | H9: 1112-KR-001 | I9: 현금 - 원 (HANA) | J9: 0 | K9: 12000500 | L9: KRW | M9: 1 | O9: 12000500 | P9: 201-910031-85704 | R9: HANA_Bank 하나은행(85704) | W9: [KR Inv_202411] VNEULSA01_Kummyung_Real estate transaction amount_KRW 12000000 | Z9: OFF | AG9: BANK | AH9: 통장
A10: =MID(D10,1,6) -> 202501 | B10: 250100007UP | C10: 승인 | D10: 20250102 | E10: [KR Inv_202411] VNEULSA01_Kummyung_Real estate transaction amount_KRW 12000000 | H10: 2202-00-001 | I10: 기타미지급금 | J10: 12000000 | K10: 0 | L10: KRW | M10: 1 | N10: 12000000 | P10: 4118183990 | R10: (유)늘샘쏠라에너지 | W10: [KR Inv_202411] VNEULSA01_Kummyung_Real estate transaction amount_KRW 12000000 | Z10: OFF | AG10: BANK | AH10: 통장
A11: =MID(D11,1,6) -> 202501 | B11: 250100007UP | C11: 승인 | D11: 20250102 | E11: [KR Inv_202411] VNEULSA01_Kummyung_Real estate transaction amount_KRW 12000000 | H11: 5301-00-000 | I11: 은행 수수료 | J11: 500 | K11: 0 | L11: KRW | M11: 1 | N11: 500 | P11: 201-910031-85704 | R11: HANA_Bank 하나은행(85704) | W11: Bank charge | Z11: OFF | AG11: BANK | AH11: 통장
A12: =MID(D12,1,6) -> 202501 | B12: 250100008UP | C12: 승인 | D12: 20250102 | E12: Issuance Fee payment | H12: 1112-KR-001 | I12: 현금 - 원 (HANA) | J12: 0 | K12: 4400 | L12: KRW | M12: 1 | O12: 4400 | P12: 201-910031-85704 | R12: HANA_Bank 하나은행(85704) | W12: Issuance Fee payment | Z12: OFF | AG12: BANK | AH12: 통장
A13: =MID(D13,1,6) -> 202501 | B13: 250100008UP | C13: 승인 | D13: 20250102 | E13: Issuance Fee payment | H13: 2202-00-001 | I13: 기타미지급금 | J13: 4400 | K13: 0 | L13: KRW | M13: 1 | N13: 4400 | P13: 2028114695 | R13: HANA BANK (주)하나은행 | W13: Issuance Fee payment | Z13: OFF | AG13: BANK | AH13: 통장
A14: =MID(D14,1,6) -> 202501 | B14: 250100009UP | C14: 승인 | D14: 20250108 | E14: [KR Inv_202501] VCOMNAM01_Project Phantom - Jeju Air Passenger Plane Crash Victim Charity_KRW 20000000 | H14: 1112-KR-001 | I14: 현금 - 원 (HANA) | J14: 0 | K14: 20000000 | L14: KRW | M14: 1 | O14: 20000000 | P14: 201-910031-85704 | R14: HANA_Bank 하나은행(85704) | W14: [KR Inv_202501] VCOMNAM01_Project Phantom - Jeju Air Passenger Plane Crash Victim Charity_KRW 20000000 | Z14: OFF | AG14: BANK | AH14: 통장
A15: =MID(D15,1,6) -> 202501 | B15: 250100009UP | C15: 승인 | D15: 20250108 | E15: [KR Inv_202501] VCOMNAM01_Project Phantom - Jeju Air Passenger Plane Crash Victim Charity_KRW 20000000 | H15: 5319-00-000 | I15: 기부금 | J15: 20000000 | K15: 0 | L15: KRW | M15: 1 | N15: 20000000 | P15: 4098209674 | R15: 사회복지법인 사회복지공동모금회 전라남도지회 | W15: [KR Inv_202501] VCOMNAM01_Project Phantom - Jeju Air Passenger Plane Crash Victim Charity_KRW 20000000 | Z15: OFF | AG15: BANK | AH15: 통장
A16: =MID(D16,1,6) -> 202501 | B16: 250100002UP | C16: 승인 | D16: 20250110 | E16: (HTX)_12월 관리비 | H16: 5101-00-000 | I16: 관리 수수료 비용 | J16: 333100 | K16: 0 | L16: KRW | M16: 1 | N16: 333100 | P16: 1168268413 | R16: 세정아울렛 관리단 | W16: 12월 관리비_세정아울렛 관리단 | Z16: OFF | AG16: PTI | AH16: 매입세금계산서
A17: =MID(D17,1,6) -> 202501 | B17: 250100002UP | C17: 승인 | D17: 20250110 | E17: (HTX)_12월 관리비 | H17: 2407-00-000 | I17: 부가세대급금 | J17: 33310 | K17: 0 | L17: KRW | M17: 1 | N17: 33310 | P17: 1168268413 | R17: 세정아울렛 관리단 | W17: VAT_12월 관리비_세정아울렛 관리단 | Z17: OFF | AG17: PTI | AH17: 매입세금계산서
A18: =MID(D18,1,6) -> 202501 | B18: 250100002UP | C18: 승인 | D18: 20250110 | E18: (HTX)_12월 관리비 | H18: 2202-00-001 | I18: 기타미지급금 | J18: 0 | K18: 366410 | L18: KRW | M18: 1 | O18: 366410 | P18: 1168268413 | R18: 세정아울렛 관리단 | W18: 12월 관리비_세정아울렛 관리단 | Z18: OFF | AG18: PTI | AH18: 매입세금계산서
A19: =MID(D19,1,6) -> 202501 | B19: 250100010UP | C19: 승인 | D19: 20250117 | E19: [KR Inv_202501] VSEJUNG01_Kummyung office maintenance fee_KRW 366,410 | H19: 1112-KR-001 | I19: 현금 - 원 (HANA) | J19: 0 | K19: 366410 | L19: KRW | M19: 1 | O19: 366410 | P19: 201-910031-85704 | R19: HANA_Bank 하나은행(85704) | W19: [KR Inv_202501] VSEJUNG01_Kummyung office maintenance fee_KRW 366,410 | Z19: OFF | AG19: BANK | AH19: 통장
A20: =MID(D20,1,6) -> 202501 | B20: 250100010UP | C20: 승인 | D20: 20250117 | E20: [KR Inv_202501] VSEJUNG01_Kummyung office maintenance fee_KRW 366,410 | H20: 2202-00-001 | I20: 기타미지급금 | J20: 366410 | K20: 0 | L20: KRW | M20: 1 | N20: 366410 | P20: 1168268413 | R20: 세정아울렛 관리단 | W20: [KR Inv_202501] VSEJUNG01_Kummyung office maintenance fee_KRW 366,410 | Z20: OFF | AG20: BANK | AH20: 통장
A21: =MID(D21,1,6) -> 202501 | B21: 250100003UP | C21: 승인 | D21: 20250131 | E21: (HTX)_용역보수 | H21: 5249-00-000 | I21: 기타 법률 및 전문 수수료 | J21: 1400000 | K21: 0 | L21: KRW | M21: 1 | N21: 1400000 | P21: 1028134334 | R21: KPMG 삼정회계법인 | W21: 용역보수_KPMG 삼정회계법인 | Z21: OFF | AG21: PTI | AH21: 매입세금계산서
A22: =MID(D22,1,6) -> 202501 | B22: 250100003UP | C22: 승인 | D22: 20250131 | E22: (HTX)_용역보수 | H22: 2407-00-000 | I22: 부가세대급금 | J22: 140000 | K22: 0 | L22: KRW | M22: 1 | N22: 140000 | P22: 1028134334 | R22: KPMG 삼정회계법인 | W22: VAT_용역보수_KPMG 삼정회계법인 | Z22: OFF | AG22: PTI | AH22: 매입세금계산서
A23: =MID(D23,1,6) -> 202501 | B23: 250100003UP | C23: 승인 | D23: 20250131 | E23: (HTX)_용역보수 | H23: 2202-00-001 | I23: 기타미지급금 | J23: 0 | K23: 1540000 | L23: KRW | M23: 1 | O23: 1540000 | P23: 1028134334 | R23: KPMG 삼정회계법인 | W23: 용역보수_KPMG 삼정회계법인 | Z23: OFF | AG23: PTI | AH23: 매입세금계산서
A24: =MID(D24,1,6) -> 202501 | B24: 250100004UP | C24: 승인 | D24: 20250131 | E24: (HTX)_FY2024 Q4 MSA Chargeback | H24: 2203-00-000 | I24: 관계사미지급금 | J24: 147977176 | K24: 0 | L24: KRW | M24: 1 | N24: 147977176 | P24: 5028400374 | R24: ECSK BO 에퀴스센트럴서비스코리아피티이엘티디 (영업소) | W24: FY2024 Q4 MSA Chargeback_ECSK BO 에퀴스센트럴서비스코리아피티이엘티디 (영업소) | Z24: OFF | AG24: PTI | AH24: 매입세금계산서
A25: =MID(D25,1,6) -> 202501 | B25: 250100004UP | C25: 승인 | D25: 20250131 | E25: (HTX)_FY2024 Q4 MSA Chargeback | H25: 2407-00-000 | I25: 부가세대급금 | J25: 14797717 | K25: 0 | L25: KRW | M25: 1 | N25: 14797717 | P25: 5028400374 | R25: ECSK BO 에퀴스센트럴서비스코리아피티이엘티디 (영업소) | W25: VAT_FY2024 Q4 MSA Chargeback_ECSK BO 에퀴스센트럴서비스코리아피티이엘티디 (영업소) | Z25: OFF | AG25: PTI | AH25: 매입세금계산서
A26: =MID(D26,1,6) -> 202501 | B26: 250100004UP | C26: 승인 | D26: 20250131 | E26: (HTX)_FY2024 Q4 MSA Chargeback | H26: 2203-00-000 | I26: 관계사미지급금 | J26: 0 | K26: 162774893 | L26: KRW | M26: 1 | O26: 162774893 | P26: 5028400374 | R26: ECSK BO 에퀴스센트럴서비스코리아피티이엘티디 (영업소) | W26: FY2024 Q4 MSA Chargeback_ECSK BO 에퀴스센트럴서비스코리아피티이엘티디 (영업소) | Z26: OFF | AG26: PTI | AH26: 매입세금계산서
A27: =MID(D27,1,6) -> 202501 | B27: 250100005UP | C27: 승인 | D27: 20250131 | E27: VAT Return for 2024.4Q | H27: 2407-00-000 | I27: 부가세대급금 | J27: 0 | K27: 445000 | L27: KRW | M27: 1 | O27: 445000 | P27: 1028134334 | R27: KPMG 삼정회계법인 | W27: VAT Return for 2024.4Q | Z27: OFF | AG27: ETC | AH27: 수기입력
A28: =MID(D28,1,6) -> 202501 | B28: 250100005UP | C28: 승인 | D28: 20250131 | E28: VAT Return for 2024.4Q | H28: 2407-00-000 | I28: 부가세대급금 | J28: 0 | K28: 350000 | L28: KRW | M28: 1 | O28: 350000 | P28: 1048617068 | R28: JIPYONG LLC.법무법인(유한) 지평 | W28: VAT Return for 2024.4Q | Z28: OFF | AG28: ETC | AH28: 수기입력
A29: =MID(D29,1,6) -> 202501 | B29: 250100005UP | C29: 승인 | D29: 20250131 | E29: VAT Return for 2024.4Q | H29: 2407-00-000 | I29: 부가세대급금 | J29: 0 | K29: 1200000 | L29: KRW | M29: 1 | O29: 1200000 | P29: 1608101862 | R29: 유한회사 삼형 | W29: VAT Return for 2024.4Q | Z29: OFF | AG29: ETC | AH29: 수기입력
A30: =MID(D30,1,6) -> 202501 | B30: 250100005UP | C30: 승인 | D30: 20250131 | E30: VAT Return for 2024.4Q | H30: 2407-00-000 | I30: 부가세대급금 | J30: 0 | K30: 115000 | L30: KRW | M30: 1 | O30: 115000 | P30: 2018112563 | R30: Lee&Ko 법무법인(유한) 광장 | W30: VAT Return for 2024.4Q | Z30: OFF | AG30: ETC | AH30: 수기입력
A31: =MID(D31,1,6) -> 202501 | B31: 250100005UP | C31: 승인 | D31: 20250131 | E31: VAT Return for 2024.4Q | H31: 2407-00-000 | I31: 부가세대급금 | J31: 0 | K31: 800 | L31: KRW | M31: 1 | O31: 800 | P31: 2028114695 | R31: HANA BANK (주)하나은행 | W31: VAT Return for 2024.4Q | Z31: OFF | AG31: ETC | AH31: 수기입력
A32: =MID(D32,1,6) -> 202501 | B32: 250100005UP | C32: 승인 | D32: 20250131 | E32: VAT Return for 2024.4Q | H32: 2407-00-000 | I32: 부가세대급금 | J32: 0 | K32: 19627885 | L32: KRW | M32: 1 | O32: 19627885 | P32: 5028400374 | R32: ECSK BO 에퀴스센트럴서비스코리아피티이엘티디 (영업소) | W32: VAT Return for 2024.4Q | Z32: OFF | AG32: ETC | AH32: 수기입력
A33: =MID(D33,1,6) -> 202501 | B33: 250100005UP | C33: 승인 | D33: 20250131 | E33: VAT Return for 2024.4Q | H33: 2407-00-000 | I33: 부가세대급금 | J33: 0 | K33: 200000 | L33: KRW | M33: 1 | O33: 200000 | P33: 6768103123 | R33: 유한회사 대연애드 | W33: VAT Return for 2024.4Q | Z33: OFF | AG33: ETC | AH33: 수기입력
A34: =MID(D34,1,6) -> 202501 | B34: 250100005UP | C34: 승인 | D34: 20250131 | E34: VAT Return for 2024.4Q | H34: 2407-00-000 | I34: 부가세대급금 | J34: 0 | K34: 108000 | L34: KRW | M34: 1 | O34: 108000 | P34: 7121001566 | R34: 이솝부동산중개사무소 | W34: VAT Return for 2024.4Q | Z34: OFF | AG34: ETC | AH34: 수기입력
A35: =MID(D35,1,6) -> 202501 | B35: 250100005UP | C35: 승인 | D35: 20250131 | E35: VAT Return for 2024.4Q | H35: 1214-00-000 | I35: 기타미수금 | J35: 22046685 | K35: 0 | L35: KRW | M35: 1 | N35: 22046685 | P35: TAX412 | R35: Naju Tax Office 나주세무서 | W35: VAT Return for 2024.4Q | Z35: OFF | AG35: ETC | AH35: 수기입력
A36: =MID(D36,1,6) -> 202501 | B36: 250100011UP | C36: 승인 | D36: 20250131 | E36: 이자지급 (20억, 23.03.31-26.03.31, 변동금리) | H36: 1112-KR-005 | I36: 현금 - 원 (신협) | J36: 0 | K36: 8662250 | L36: KRW | M36: 1 | O36: 8662250 | P36: 131-022-007238 | R36: 신협 (007238) | W36: 이자지급 (20억, 23.03.31-26.03.31, 변동금리) | Z36: OFF | AG36: BANK | AH36: 통장
A37: =MID(D37,1,6) -> 202501 | B37: 250100011UP | C37: 승인 | D37: 20250131 | E37: 이자지급 (20억, 23.03.31-26.03.31, 변동금리) | H37: 2204-00-002 | I37: 미지급이자비용 - 일반 대출 - 단기 | J37: 8662250 | K37: 0 | L37: KRW | M37: 1 | N37: 8662250 | P37: 4118202510 | R37: 목포신용협동조합 | W37: 이자지급 (20억, 23.03.31-26.03.31, 변동금리) | Z37: OFF | AG37: BANK | AH37: 통장
A38: =MID(D38,1,6) -> 202501 | B38: 250100012UP | C38: 승인 | D38: 20250131 | E38: Loan Interest_목포신협 to 금명 (KRW 2,000,000,000_5.1% 변동금리) | H38: 2204-00-002 | I38: 미지급이자비용 - 일반 대출 - 단기 | J38: 0 | K38: 8662250 | L38: KRW | M38: 1 | O38: 8662250 | P38: 4118202510 | R38: 목포신용협동조합 | W38: Loan Interest_목포신협 to 금명 (KRW 2,000,000,000_5.1% 변동금리) | Z38: OFF | AG38: ETC | AH38: 수기입력
A39: =MID(D39,1,6) -> 202501 | B39: 250100012UP | C39: 승인 | D39: 20250131 | E39: Loan Interest_목포신협 to 금명 (KRW 2,000,000,000_5.1% 변동금리) | H39: 5719-00-000 | I39: 이자비용 - 일반 | J39: 8662250 | K39: 0 | L39: KRW | M39: 1 | N39: 8662250 | P39: 4118202510 | R39: 목포신용협동조합 | W39: Loan Interest_목포신협 to 금명 (KRW 2,000,000,000_5.1% 변동금리) | Z39: OFF | AG39: ETC | AH39: 수기입력
A40: =MID(D40,1,6) -> 202501 | B40: 250100013UP | C40: 승인 | D40: 20250131 | E40: Office rent | H40: 5281-00-000 | I40: 지급임차료 | J40: 1000000 | K40: 0 | L40: KRW | M40: 1 | N40: 1000000 | P40: 1608101862 | R40: 유한회사 삼형 | W40: Office rent | Z40: OFF | AG40: ETC | AH40: 수기입력
...

Sheet journal 2025_EY
A1: Posting Date | B1: Document No. | C1: G/L Account No. | D1: G/L Account Name | E1: Vendor Code | F1: Description | G1: Comment | H1: Debit Amount (LCY) | I1: Credit Amount (LCY) | J1: Amount (LCY) | K1: Bal. Account Type | L1: Bal. Account No. | M1: Currency Code | N1: Gen. Posting Type | O1: Gen. Bus. Posting Group | P1: Gen. Prod. Posting Group | Q1: Created At
A2: 45747 | B2: GJ25-0072 | C2: 6402-00-002 | D2: FX - unrealized gains - others / 외화환산손실 | E2: IEEKR001 | F2: 231 EEKHPL_Unsecured Loan Agreement(USD 260,000) | H2: 3231800 | I2: 0 | J2: 3231800 | K2: G/L Account | L2: 2102-00-000 | N2: Purchase | P2: GENERAL | Q2: 45763.167
A3: 45747 | B3: GJ25-0071 | C3: 6402-00-002 | D3: FX - unrealized gains - others / 외화환산손실 | E3: IEEKR001 | F3: 230 EEKHPL_Unsecured Loan Agreement(USD 1,500,000) | H3: 18645000 | I3: 0 | J3: 18645000 | K3: G/L Account | L3: 2102-00-000 | N3: Purchase | P3: GENERAL | Q3: 45763.167
A4: 45747 | B4: GJ25-0073 | C4: 6402-00-002 | D4: FX - unrealized gains - others / 외화환산손실 | E4: IECSG001 | F4: EQUIS InterCo Billings_ECSSPL | H4: 41674 | I4: 0 | J4: 41674 | K4: Vendor | L4: IECSG001 | N4: Purchase | P4: GENERAL | Q4: 45763.167
A5: 45747 | B5: GJ25-0063 | C5: 5719-00-000 | D5: Interest expense - External / 이자비용 - 일반 | E5: VMOKPOC01 | F5: Loan Interest_목포신협 to 금명 (KRW 2,000,000,000_5.1% 변동금리) | H5: 8663013 | I5: 0 | J5: 8663013 | K5: G/L Account | L5: 2204-00-002 | N5: Purchase | P5: GENERAL | Q5: 45762.889
A6: 45747 | B6: GJ25-0068 | C6: 5717-00-000 | D6: Interest expense - InterCo / 이자비용 - 회사 간 대출 | E6: IEEKR005 | F6: Loan Interest_EEK2 to 금명 (KRW 1,321,408,000_14%) | H6: 15712084 | I6: 0 | J6: 15712084 | K6: G/L Account | L6: 2204-00-001 | N6: Purchase | P6: GENERAL | Q6: 45763.117
A7: 45747 | B7: GJ25-0067 | C7: 5717-00-000 | D7: Interest expense - InterCo / 이자비용 - 회사 간 대출 | E7: IEEKR005 | F7: 수정분개 Loan Interest_EEK2 to 금명 (KRW 1,321,408,000_14%) | H7: 0 | I7: 14191560 | J7: -14191560 | K7: G/L Account | L7: 2204-00-001 | N7: Purchase | P7: GENERAL | Q7: 45763.117
A8: 45747 | B8: GJ25-0065 | C8: 5717-00-000 | D8: Interest expense - InterCo / 이자비용 - 회사 간 대출 | E8: IEEKR005 | F8: Loan Interest_EEK2 to 금명 (KRW 1,321,408,000_14%) | H8: 14191560 | I8: 0 | J8: 14191560 | K8: G/L Account | L8: 2204-00-001 | N8: Purchase | P8: GENERAL | Q8: 45762.889
A9: 45747 | B9: GJ25-0066 | C9: 5281-00-000 | D9: Rent / 지급임차료 | E9: VSAMHYO01 | F9: Office rent | H9: 1000000 | I9: 0 | J9: 1000000 | K9: G/L Account | L9: 1232-00-000 | N9: Purchase | P9: GENERAL | Q9: 45762.889
A10: 45747 | B10: GJ25-0064 | C10: 2204-00-002 | D10: Accrued interest expense - General Loan - Short term / 미지급이자비용 - 일반 대출 - 단기 | E10: VMOKPOC01 | F10: 이자지급 (20억, 23.03.31-26.03.31, 변동금리) | H10: 8663013 | I10: 0 | J10: 8663013 | K10: Bank Account | L10: SHINHYUP-KRW | M10: KRW | N10: Purchase | P10: GENERAL | Q10: 45762.889
A11: 45747 | B11: GJ25-0063 | C11: 2204-00-002 | D11: Accrued interest expense - General Loan - Short term / 미지급이자비용 - 일반 대출 - 단기 | E11: VMOKPOC01 | F11: Loan Interest_목포신협 to 금명 (KRW 2,000,000,000_5.1% 변동금리) | H11: 0 | I11: 8663013 | J11: -8663013 | K11: G/L Account | L11: 5719-00-000 | N11: Purchase | P11: GENERAL | Q11: 45762.889
A12: 45747 | B12: GJ25-0068 | C12: 2204-00-001 | D12: Accrued interest expense - Loan - Long term / 미지급이자비용 - 관계사 대출 - 장기 | E12: IEEKR005 | F12: Loan Interest_EEK2 to 금명 (KRW 1,321,408,000_14%) | H12: 0 | I12: 15712084 | J12: -15712084 | K12: G/L Account | L12: 5717-00-000 | N12: Purchase | P12: GENERAL | Q12: 45763.117
A13: 45747 | B13: GJ25-0067 | C13: 2204-00-001 | D13: Accrued interest expense - Loan - Long term / 미지급이자비용 - 관계사 대출 - 장기 | E13: IEEKR005 | F13: 수정분개 Loan Interest_EEK2 to 금명 (KRW 1,321,408,000_14%) | H13: 14191560 | I13: 0 | J13: 14191560 | K13: G/L Account | L13: 5717-00-000 | N13: Purchase | P13: GENERAL | Q13: 45763.117
A14: 45747 | B14: GJ25-0065 | C14: 2204-00-001 | D14: Accrued interest expense - Loan - Long term / 미지급이자비용 - 관계사 대출 - 장기 | E14: IEEKR005 | F14: Loan Interest_EEK2 to 금명 (KRW 1,321,408,000_14%) | H14: 0 | I14: 14191560 | J14: -14191560 | K14: G/L Account | L14: 5717-00-000 | N14: Purchase | P14: GENERAL | Q14: 45762.889
A15: 45747 | B15: GJ25-0073 | C15: 2203-00-000 | D15: Intercompany Payable / 관계사미지급금 | E15: IECSG001 | F15: EQUIS InterCo Billings_ECSSPL | H15: 0 | I15: 41674 | J15: -41674 | K15: G/L Account | L15: 6402-00-002 | Q15: 45763.167
A16: 45747 | B16: GJ25-0072 | C16: 2102-00-000 | D16: Intercompany loans / 관계사 대출 - 장기 | E16: IEEKR001 | F16: 231 EEKHPL_Unsecured Loan Agreement(USD 260,000) | H16: 0 | I16: 3231800 | J16: -3231800 | K16: G/L Account | L16: 6402-00-002 | N16: Purchase | P16: GENERAL | Q16: 45763.167
A17: 45747 | B17: GJ25-0071 | C17: 2102-00-000 | D17: Intercompany loans / 관계사 대출 - 장기 | E17: IEEKR001 | F17: 230 EEKHPL_Unsecured Loan Agreement(USD 1,500,000) | H17: 0 | I17: 18645000 | J17: -18645000 | K17: G/L Account | L17: 6402-00-002 | N17: Purchase | P17: GENERAL | Q17: 45763.167
A18: 45747 | B18: GJ25-0066 | C18: 1232-00-000 | D18: Prepaid expenses / 선급비용 | E18: VSAMHYO01 | F18: Office rent | H18: 0 | I18: 1000000 | J18: -1000000 | K18: G/L Account | L18: 5281-00-000 | N18: Purchase | P18: GENERAL | Q18: 45762.889
A19: 45747 | B19: GJ25-0064 | C19: 1112-KR-005 | D19: Cash - KRW (SHINHYUP) / 현금 - 원 (신협) | E19: VMOKPOC01 | F19: 이자지급 (20억, 23.03.31-26.03.31, 변동금리) | H19: 0 | I19: 8663013 | J19: -8663013 | K19: G/L Account | L19: 2204-00-002 | M19: KRW | Q19: 45762.889
A20: 45743 | B20: GJ25-0062 | C20: 2202-00-001 | D20: Other payable / 기타미지급금 | E20: VHYCHNG01 | F20: [KR Inv_202504] VHYCHNG01_PJ PhantomKummyung CSR - 2025 Dialogue with Citizens Event Support (Sinan | H20: 905000 | I20: 0 | J20: 905000 | K20: Bank Account | L20: HANA-KRW | M20: KRW | Q20: 45762.889
A21: 45743 | B21: GJ25-0061 | C21: 2202-00-001 | D21: Other payable / 기타미지급금 | E21: VPRDLTD01 | F21: [KR Inv_202504] VHYCHNG01_PJ Phantom_Kummyung CSR - 2025 Dialogue with Citizens Event Support (Sinan | H21: 3000000 | I21: 0 | J21: 3000000 | K21: Bank Account | L21: HANA-KRW | M21: KRW | Q21: 45762.889
A22: 45743 | B22: GJ25-0062 | C22: 1112-KR-001 | D22: Cash - KRW (HANA) / 현금 - 원 (HANA) | E22: VHYCHNG01 | F22: [KR Inv_202504] VHYCHNG01_PJ PhantomKummyung CSR - 2025 Dialogue with Citizens Event Support (Sinan | H22: 0 | I22: 905000 | J22: -905000 | K22: G/L Account | L22: 2202-00-001 | M22: KRW | Q22: 45762.889
A23: 45743 | B23: GJ25-0061 | C23: 1112-KR-001 | D23: Cash - KRW (HANA) / 현금 - 원 (HANA) | E23: VPRDLTD01 | F23: [KR Inv_202504] VHYCHNG01_PJ Phantom_Kummyung CSR - 2025 Dialogue with Citizens Event Support (Sinan | H23: 0 | I23: 3000000 | J23: -3000000 | K23: G/L Account | L23: 2202-00-001 | M23: KRW | Q23: 45762.889
A24: 45737 | B24: GJ25-0054 | C24: 5249-00-000 | D24: Other legal and professional fees / 기타 법률 및 전문 수수료 | E24: VKPMCOR01 | F24: 용역보수_KPMG 삼정회계법인 | H24: 850000 | I24: 0 | J24: 850000 | K24: Vendor | L24: VKPMCOR01 | N24: Purchase | P24: GENERAL | Q24: 45762.889
A25: 45737 | B25: GJ25-0054 | C25: 2407-00-000 | D25: GST/VAT receivable / 부가세대급금 | E25: VKPMCOR01 | F25: 용역보수_KPMG 삼정회계법인 | H25: 85000 | I25: 0 | J25: 85000 | K25: G/L Account | Q25: 45762.889
A26: 45737 | B26: GJ25-0053 | C26: 2202-00-001 | D26: Other payable / 기타미지급금 | E26: VKIMYUN01 | F26: 소유권이전 (분매리134-249외 4필지, 총 2100평)_김윤석 법무사 | H26: 0 | I26: 330000 | J26: -330000 | K26: G/L Account | Q26: 45762.889
A27: 45737 | B27: GJ25-0054 | C27: 2202-00-001 | D27: Other payable / 기타미지급금 | E27: VKPMCOR01 | F27: 용역보수_KPMG 삼정회계법인 | H27: 0 | I27: 935000 | J27: -935000 | K27: G/L Account | L27: 5249-00-000 | Q27: 45762.889
A28: 45737 | B28: GJ25-0060 | C28: 1712-00-000 | D28: Leasehold land / 토지 | E28: VSACGOO01 | F28: [KR Inv_202503] VTAXLOC01_Project Phantom_Kummyung Land Acquisition Tax Payment_KRW 11592000 | H28: 11592000 | I28: 0 | J28: 11592000 | K28: Bank Account | L28: HANA-KRW | M28: KRW | N28: Purchase | P28: GENERAL | Q28: 45762.889
A29: 45737 | B29: GJ25-0053 | C29: 1712-00-000 | D29: Leasehold land / 토지 | E29: VKIMYUN01 | F29: VAT_소유권이전 (분매리134-249외 4필지, 총 2100평)_김윤석 법무사 | H29: 30000 | I29: 0 | J29: 30000 | K29: G/L Account | N29: Purchase | P29: GENERAL | Q29: 45762.889
A30: 45737 | B30: GJ25-0053 | C30: 1712-00-000 | D30: Leasehold land / 토지 | E30: VKIMYUN01 | F30: 소유권이전 (분매리134-249외 4필지, 총 2100평)_김윤석 법무사 | H30: 300000 | I30: 0 | J30: 300000 | K30: G/L Account | N30: Purchase | P30: GENERAL | Q30: 45762.889
A31: 45737 | B31: GJ25-0060 | C31: 1112-KR-001 | D31: Cash - KRW (HANA) / 현금 - 원 (HANA) | E31: VSACGOO01 | F31: [KR Inv_202503] VTAXLOC01_Project Phantom_Kummyung Land Acquisition Tax Payment_KRW 11592000 | H31: 0 | I31: 11592000 | J31: -11592000 | K31: G/L Account | L31: 1712-00-000 | M31: KRW | Q31: 45762.889
A32: 45736 | B32: GJ25-0059 | C32: 2202-00-001 | D32: Other payable / 기타미지급금 | E32: VSEJUNG01 | F32: [KR Inv_202503] VSEJUNG01_Kummyung office maintenance fee_KRW 439,610 | H32: 439610 | I32: 0 | J32: 439610 | K32: Bank Account | L32: HANA-KRW | M32: KRW | Q32: 45762.889
A33: 45736 | B33: GJ25-0058 | C33: 2202-00-001 | D33: Other payable / 기타미지급금 | E33: VKPMCOR01 | F33: [KR Inv_202503] VKPMCOR01_KPMG Acct Service for Jan'24_KRW 73372750 | H33: 1540000 | I33: 0 | J33: 1540000 | K33: Bank Account | L33: HANA-KRW | M33: KRW | Q33: 45762.889
A34: 45736 | B34: GJ25-0057 | C34: 2202-00-001 | D34: Other payable / 기타미지급금 | E34: VKPMCOR01 | F34: [KR Inv_202501] VKPMCOR01_KPMG Acct Service for Dec'24_KRW 31141000 | H34: 715000 | I34: 0 | J34: 715000 | K34: Bank Account | L34: HANA-KRW | M34: KRW | Q34: 45762.889
A35: 45736 | B35: GJ25-0059 | C35: 1112-KR-001 | D35: Cash - KRW (HANA) / 현금 - 원 (HANA) | E35: VSEJUNG01 | F35: [KR Inv_202503] VSEJUNG01_Kummyung office maintenance fee_KRW 439,610 | H35: 0 | I35: 439610 | J35: -439610 | K35: Vendor | L35: VSEJUNG01 | M35: KRW | Q35: 45762.889
A36: 45736 | B36: GJ25-0058 | C36: 1112-KR-001 | D36: Cash - KRW (HANA) / 현금 - 원 (HANA) | E36: VKPMCOR01 | F36: [KR Inv_202503] VKPMCOR01_KPMG Acct Service for Jan'24_KRW 73372750 | H36: 0 | I36: 1540000 | J36: -1540000 | K36: Vendor | L36: VKPMCOR01 | M36: KRW | Q36: 45762.889
A37: 45736 | B37: GJ25-0057 | C37: 1112-KR-001 | D37: Cash - KRW (HANA) / 현금 - 원 (HANA) | E37: VKPMCOR01 | F37: [KR Inv_202501] VKPMCOR01_KPMG Acct Service for Dec'24_KRW 31141000 | H37: 0 | I37: 715000 | J37: -715000 | K37: Vendor | L37: VKPMCOR01 | M37: KRW | Q37: 45762.889
A38: 45733 | B38: GJ25-0052 | C38: 5263-00-000 | D38: Advertising / 광고비용 | E38: VHYCHNG01 | F38: 떡류_현창떡집 | H38: 822727 | I38: 0 | J38: 822727 | K38: G/L Account | L38: 2202-00-001 | N38: Purchase | P38: GENERAL | Q38: 45762.889
A39: 45733 | B39: GJ25-0052 | C39: 2407-00-000 | D39: GST/VAT receivable / 부가세대급금 | E39: VHYCHNG01 | F39: 떡류_현창떡집 | H39: 82273 | I39: 0 | J39: 82273 | K39: G/L Account | Q39: 45762.889
A40: 45733 | B40: GJ25-0052 | C40: 2202-00-001 | D40: Other payable / 기타미지급금 | E40: VHYCHNG01 | F40: 떡류_현창떡집 | H40: 0 | I40: 905000 | J40: -905000 | K40: G/L Account | L40: 5263-00-000 | Q40: 45762.889
...

Sheet 고객사 확인 요청 사항
A1: 1 | B1: EY 문의 사항
B2: *압해도 태양광 발전사업 - 1차 운영비 지급 건 -아직 자산화 하지 않고, 기타 운영 비용으로 처리 하였는데, 토지 매입 관련 비용으로 자산화 처리 해야 하는지 여부 확인 부탁드립니다. | L2: 건설중 자산 or 토지
B3: 4/11/2025 | C3: 22 | D3: 5108-00-000 | E3: Other operating expense / 기타 운영 비용 | F3: 압해도 태양광 발전사업 개발용역 6-1_늘샘그린에너지 주식회사 | G3: 20000000 | H3: 0
B4: 4/11/2025 | C4: 22 | D4: 2407-00-000 | E4: GST/VAT receivable / 부가세대급금 | F4: 압해도 태양광 발전사업 개발용역 6-1_늘샘그린에너지 주식회사 | G4: 2000000 | H4: 0
B5: 4/11/2025 | C5: 22 | D5: 1112-KR-001 | E5: Cash - KRW (HANA) / 현금 - 원 (HANA) | F5: 압해도 태양광 발전사업 개발용역 6-1_늘샘그린에너지 주식회사 | G5: 0 | H5: 22000000
B6: Equis 답변
B7: 자산화 하라고하심
A10: P5 | B10: EY 문의 사항
B15: ECSK에서 발행된 2025 1Q 세금계산서 있음. 해당 사항 24년도 말 부로 모두 관계사 미지급금으로 재분류 된것을 확인하였으나
B16: 확인된 24년도부터 지속적으로 발생된것으로 보아 계약서가 있을것으로 사려됨
B17: 해당 사항에 대한 증빙이 현재 확인되지 않음으로 관련 서류 요청드립니다.

Sheet BS
A2: 재 무 상 태 표
A3: 2026/03/31
A4: 회 사 명 : 금명 유한회사 | G4: (단위:원)
B5: 과목 | C5: 46053 | D5: 46081 | E5: 46112 | F5: 2025-12-31 | G5: 증가(감소)액 | H5: 증가(감소)율
B6: 자산
B7: 유동자산 | C7: =C8 -> 637162948 | D7: =D8 -> 161358890 | E7: =E8 -> 2543688929 | F7: 1569336905 | G7: =E7-F7 -> 974352024 | H7: 3.48205
B8: 당좌자산 | C8: =C9+C12+C13+C14+C15+C16 -> 637162948 | D8: =D9+D12+D13+D14+D15+D16 -> 161358890 | E8: =E9+E12+E13+E14+E15+E16 -> 2543688929 | F8: 1569336905 | G8: =E8-F8 -> 974352024 | H8: 3.48205
B9: 보통예금 | C9: =C10+C11 -> 291756083 | D9: =D10+D11 -> 84855919 | E9: =E10+E11 -> 2468045538 | F9: 1405309172 | G9: =E9-F9 -> 1062736366 | H9: 4.08529
B10: 현금 - 원 (HANA) | C10: 288507178 | D10: 69264438 | E10: 2467032264 | F10: 1402060267 | G10: =E10-F10 -> 1064971997 | H10: 4.52362
B11: 현금 - 원 (신협) | C11: 3248905 | D11: 15591481 | E11: 1013274 | F11: 3248905 | G11: =E11-F11 -> -2235631 | H11: -0.44571
B12: 선납세금 | C12: 340300 | D12: 340300 | E12: 374020 | F12: 340300 | G12: =E12-F12 -> 33720 | H12: 0%
B13: 기타미수금 | C13: 36539357 | D13: 22404357 | E13: 22404357 | F13: 36539357 | G13: =E13-F13 -> -14135000 | H13: 0%
B14: 선급비용 | D14: 9000000 | E14: 8000000 | G14: =E14-F14 -> 8000000 | H14: -0.18182
B15: 선급금 (유동) | G15: =E15-F15 -> 0 | H15: -1
B16: 부가세대급금 | C16: 308527208 | D16: 44758314 | E16: 44865014 | F16: 127148076 | G16: =E16-F16 -> -82283062 | H16: -0.31639
B17: 재고자산 | G17: =E17-F17 -> 0 | H17: 0%
B18: 비유동자산 | C18: =C19+C20+C24 -> 9683028144 | D18: =D19+D20+D24 -> 10014000244 | E18: =E19+E20+E24 -> 10176426194 | F18: 8577016044 | G18: =E18-F18 -> 1599410150 | H18: 0.03704
B19: 투자자산 | G19: =E19-F19 -> 0 | H19: 0%
B20: 유형자산 | C20: =SUM(C21:C22) -> 9662048144 | D20: =SUM(D21:D22) -> 9993020244 | E20: =SUM(E21:E22) -> 10155446194 | F20: 8556036044 | G20: =E20-F20 -> 1599410150 | H20: 0.03715
B21: 토지 | C21: 8772436144 | D21: 9137120244 | E21: 9299546194 | F21: 7684424044 | G21: =E21-F21 -> 1615122150 | H21: 0.03715
B22: 건설중인자산 | C22: 889612000 | D22: 855900000 | E22: 855900000 | F22: 871612000 | G22: =E22-F22 -> -15712000
B23: 무형자산 | G23: =E23-F23 -> 0 | H23: 0%
B24: 기타비유동자산 | C24: =C25 -> 20980000 | D24: =D25 -> 20980000 | E24: =E25 -> 20980000 | F24: 20980000 | G24: =E24-F24 -> 0 | H24: 0%
B25: 임차보증금 - 비유동 | C25: 20980000 | D25: 20980000 | E25: 20980000 | F25: 20980000 | G25: =E25-F25 -> 0 | H25: 0%
B26: 자산 총 계 | C26: =C18+C7 -> 10320191092 | D26: =D18+D7 -> 10175359134 | E26: =E18+E7 -> 12720115123 | F26: 10146352949 | G26: =E26-F26 -> 2573762174 | H26: 0.26765
B27: 부채 | C27: =C33+C28 -> 9906100377 | D27: =D33+D28 -> 10042633766 | E27: =E33+E28 -> 12970079959 | F27: 9317747503 | G27: =E27-F27 -> 3652332456
B28: 유동부채 | C28: =SUM(C29:C32) -> 618000028 | D28: =SUM(D29:D32) -> 761708457 | E28: =SUM(E29:E32) -> 431102093 | F28: 16535838 | G28: =E28-F28 -> 414566255 | H28: -0.9812
B29: 계약부채 | G29: =E29-F29 -> 0
B30: 기타미지급금 | C30: 10071250 | D30: 14854210 | E30: 9994450 | F30: 7091250 | G30: =E30-F30 -> 2903200 | H30: -0.81823
B31: 관계사미지급금 | C31: 600273205 | D31: 739939715 | E31: 421107643 | F31: 9446439 | G31: =E31-F31 -> 411661204 | H31: -0.99487
B32: 미지급이자비용 - 일반 대출 -단기 | C32: =7657424-1851 -> 7655573 | D32: =6916383-1851 -> 6914532 | G32: =E32-F32 -> 0
B33: 비유동부채 | C33: =SUM(C34:C36) -> 9288100349 | D33: =SUM(D34:D36) -> 9280925309 | E33: =SUM(E34:E36) -> 12538977866 | F33: 9301211665 | G33: =E33-F33 -> 3237766201 | H33: 0.51986
B34: 은행 대출 | C34: 1960000000 | D34: 1960000000 | E34: 1960000000 | F34: 1960000000 | G34: =E34-F34 -> 0 | H34: 0%
B35: 관계사 대출 - 장기 | C35: 5495810680 | D35: 5474444080 | E35: 8716784553 | F35: 5524634080 | G35: =E35-F35 -> 3192150473 | H35: 1.92593
B36: 미지급이자비용 - 관계사 대출 - 장기 | C36: 1832289669 | D36: 1846481229 | E36: 1862193313 | F36: 1816577585 | G36: =E36-F36 -> 45615728 | H36: 0.01833
B37: 부채 총 계 | C37: =C27 -> 9906100377 | D37: =D27 -> 10042633766 | E37: =E27 -> 12970079959 | F37: 9317747503 | G37: =E37-F37 -> 3652332456 | H37: 0.37045
B38: 자본 | C38: =C39+C41+C42+C45+C46 -> 414090715 | D38: =D39+D41+D42+D45+D46 -> 132725368 | E38: =E39+E41+E42+E45+E46 -> -249964836 | F38: 828605446 | G38: =E38-F38 -> -1078570282
B39: 자본금 | C39: 4004550000 | D39: 4004550000 | E39: =E40 -> 4004550000 | F39: 4004550000 | G39: =E39-F39 -> 0 | H39: 0%
B40: 보통주 | C40: 4004550000 | D40: 4004550000 | E40: 4004550000 | F40: 4004550000 | G40: =E40-F40 -> 0 | H40: 0%
B41: 자본잉여금 | G41: =E41-F41 -> 0 | H41: 0%
...

Sheet IS
A2: 손 익 계 산 서
A3: 2026/01/01~2026/03/31 ( 2026/01/01~2026/12/31 )
A4: 회 사 명 : 금명 유한회사 | F4: (단위:원)
B5: 과목 | C5: 2026/01/31 | D5: 2026/02/28 | E5: 2026/03/31 | F5: 2026/01/01~2026/12/31
B6: 매출 | F6: 0
B7: 매출원가 | F7: 0
B8: 매출총이익 | F8: 0
B9: 판매비와 관리비 | C9: 557740541 | D9: 143720611 | E9: 141769435 | F9: =SUM(C9:E9) -> 843230587
B10: 관리 수수료 비용 | C10: 327870 | D10: 354330 | E10: 323510 | F10: =SUM(C10:E10) -> 1005710
B11: 공유 서비스 비용 | C11: 2049443 | F11: =SUM(C11:E11) -> 2049443
B12: 기타 법률 및 전문 수수료 | D12: 2700000 | F12: =SUM(C12:E12) -> 2700000
B13: 관리운용비용 | C13: 554311352 | D13: 139654281 | E13: 139697985 | F13: =SUM(C13:E13) -> 833663618
B14: 지급임차료 | C14: 1000000 | D14: 1000000 | E14: 1000000 | F14: =SUM(C14:E14) -> 3000000
B15: 광고비용 | F15: =SUM(C15:E15) -> 0
B16: 은행 수수료 | C16: 51876 | D16: 12000 | E16: 8400 | F16: =SUM(C16:E16) -> 72276
B17: 기부금 | F17: =SUM(C17:E17) -> 0
B18: 기타 운영 비용 | F18: =SUM(C18:E18) -> 0
B19: 여비교통비 | F19: =SUM(C19:E19) -> 0
B20: 세금과 공과 | E20: 739540 | F20: =SUM(C20:E20) -> 739540
B21: 영업이익 | C21: =-C9 -> -557740541 | D21: =-D9 -> -143720611 | E21: =-E9 -> -141769435 | F21: =SUM(C21:E21) -> -843230587
B22: 영업외수익 | C22: -11135400 | D22: -8254600 | E22: -19170929 | F22: =SUM(C22:E22) -> -38560929
B23: 이자수익 - 은행 | E23: 219071 | F23: =SUM(C23:E23) -> 219071
B24: 외화환산이익 | C24: -11135400 | D24: 8254600 | E24: -19390000 | F24: =SUM(C24:E24) -> -22270800
B25: 잡이익 | F25: =SUM(C25:E25) -> 0
B26: 외환차익 | F26: =SUM(C26:E26) -> 0
B27: 영업외비용 | C27: =SUM(C28:C32) -> 5767038 | D27: =SUM(D28:D32) -> 8041888 | E27: =SUM(E28:E32) -> 221747989 | F27: =SUM(C27:E27) -> 235556915
B28: 외환차손 | C28: 410005 | E28: 70172431 | F28: =SUM(C28:E28) -> 70582436
B29: 잡손실 | C29: 18030 | D29: 33716 | E29: 18350 | F29: =SUM(C29:E29) -> 70096
B30: 이자비용 - 회사 간 대출 | C30: 15712084 | D30: 14191560 | E30: 15712084 | F30: =SUM(C30:E30) -> 45615728
B31: 이자비용 - 일반 | C31: 7657424 | D31: 6916383 | E31: 7657424 | F31: =SUM(C31:E31) -> 22231231
B32: 외화환산손실 | C32: -18030505 | D32: -13099771 | E32: 128187700 | F32: =SUM(C32:E32) -> 97057424
B33: 기타 금융 비용 | F33: =SUM(C33:E33) -> 0
B34: 법인세 비용 차감전 순이익 | C34: =C21+C22-C27 -> -574642979 | D34: =D21+D22-D27 -> -160017099 | E34: =E21+E22-E27 -> -382688353 | F34: =SUM(C34:E34) -> -1117348431
B35: 소득세와 법인세 | F35: =SUM(C35:E35) -> 0
B36: 당기순이익 | C36: =C34 -> -574642979 | D36: =D34 -> -160017099 | E36: =E34 -> -382688353 | F36: =SUM(C36:E36) -> -1117348431
C38: =SUM(C36:C36) -> -574642979 | D38: =SUM(C36:D36) -> -734660078 | E38: =SUM(C36:E36) -> -1117348431
C39: =C21-C27+C22 -> -574642979 | D39: =D21-D27+D22 -> -160017099 | E39: =E21-E27+E22 -> -382688353
C40: =C36=C39 -> TRUE | D40: =D36=D39 -> TRUE | E40: =E36=E39 -> TRUE

Sheet TB
A1: 시산표
A2: 금명 유한회사
A3: 2026/03/01 ~ 2026/03/31
A4: 계정 | B4: 계정명 | D4: 차변 | E4: 대변
A5: 1112-KR-001 | B5: Cash - KRW (HANA) / 현금 - 원 (HANA) | C5: 69264438 | D5: 3024823473 | E5: 627055647 | F5: 2467032264
A6: 1108-KR-001 | B6: Cash - USD (HANA) / 현금 - USD (HANA) | C6: 0 | D6: 3024823473 | E6: 3024823473 | F6: 0
A7: 1112-KR-005 | B7: Cash - KRW (SHINHYUP) / 현금 - 원 (신협) | C7: 15591481 | D7: 0 | E7: 14578207 | F7: 1013274
A8: 1211-00-000 | B8: Accounts receivables / 외상매출금 | C8: 11404357 | D8: 0 | E8: 0 | F8: 11404357 | G8: ->기타미수금
A9: 1212-00-000 | B9: Income tax receivables / 선납세금 | C9: 340300 | D9: 33720 | E9: 0 | F9: 374020
A10: 1214-00-000 | B10: Other receivables / 기타미수금 | C10: 11000000 | D10: 0 | E10: 0 | F10: 11000000
A11: 1231-00-000 | B11: Deposits and advances / 임차보증금 - 비유동 | C11: 20980000 | D11: 0 | E11: 0 | F11: 20980000
A12: 1232-00-000 | B12: Prepaid expenses / 선급비용 | C12: 9000000 | D12: 0 | E12: 1000000 | F12: 8000000
A13: 1713-00-000 | B13: Land/토지 | C13: 9137120244 | D13: 173425950 | E13: 9472000 | F13: =C13+D13-E13 -> 9301074194
A14: 2407-00-000 | B14: GST/VAT receivable / 부가세대급금 | C14: 44758314 | D14: 1106700 | E14: 1000000 | F14: =C14+D14-E14 -> 44865014
A15: 1760-00-028 | B15: Construction work in progress / 건설중인 자산 | C15: 855900000 | D15: 1000000 | E15: 1000000 | F15: =C15+D15-E15 -> 855900000
A16: 자산 Total | C16: =SUM(C5:C15) -> 10175359134 | D16: =SUM(D5:D15) -> 6225213316 | E16: =SUM(E5:E15) -> 3678929327 | F16: =SUM(F5:F15) -> 12721643123
A17: 2101-00-000 | B17: Bank loans / 은행 대출 | C17: -1960000000 | F17: -1960000000
A18: 2102-00-000 | B18: Intercompany loans / 관계사 대출 - 장기 | C18: -5474444080 | D18: 3643200 | E18: 3245983673 | F18: -8716784553
A19: 2202-00-001 | B19: Other payable / 기타미지급금 | C19: -14854210 | D19: 169463860 | E19: 175604100 | F19: -20994450
A20: 2203-00-000 | B20: Intercompany Payable / 관계사미지급금 | C20: -739939715 | D20: 737890476 | E20: 419058404 | F20: -421107643
A21: 2204-00-001 | B21: Accrued interest expense - Loan - Long term / 미지급이자비용 - 관계사 대출 - 장기 | C21: -1846481229 | E21: 15712084 | F21: -1862193313
A22: 2204-00-002 | B22: Accrued interest expense - General Loan - Short term / 미지급이자비용 - 일반 대출 - 단기 | C22: -6916383 | D22: 14573807 | E22: 7657424 | F22: 0
A23: 부채 Total | C23: =SUM(C17:C22) -> -10042635617 | D23: =SUM(D17:D22) -> 925571343 | E23: =SUM(E17:E22) -> 3864015685 | F23: =SUM(F17:F22) -> -12981079959
A24: 3111-00-000 | B24: Ordinary shares / 보통주 | C24: -4004550000 | F24: -4004550000
A25: 3113-00-001 | B25: Discount on stock issuance / 주식할인 발행차금 | C25: 26321000 | F25: 26321000
A26: 3304-00-000 | B26: Loss on capital reduction / 감자차손 | C26: 1347557747 | F26: 1347557747
A27: 3401-00-000 | B27: Retained earnings / 이익 잉여금 | C27: 1802067658 | F27: 1802067658
A28: 자본 Total | C28: =SUM(C24:C27) -> -828603595 | D28: =SUM(D24:D27) -> 0 | E28: =SUM(E24:E27) -> 0 | F28: =SUM(F24:F27) -> -828603595
A29: 5101-00-000 | B29: Management fee expense / 관리 수수료 비용 | C29: 682200 | D29: 323510 | E29: 0 | F29: =C29+D29-E29 -> 1005710
A30: 5106-00-000 | B30: Shared service charges / 공유 서비스 비용 | C30: 2049443 | D30: 0 | E30: 0 | F30: =C30+D30-E30 -> 2049443
A31: 5211-00-000 | B31: Organizational expenses / 관리운용비용 | C31: 693965633 | D31: 418998395 | E31: 279300410 | F31: =C31+D31-E31 -> 833663618
A32: 5108-00-000 | B32: Other operating expense / 기타 운영 비용 | C32: 1800000 | D32: 0 | E32: 0 | F32: =C32+D32-E32 -> 1800000
A33: 5249-00-000 | B33: Other legal and professional fees / 기타 법률 및 전문 수수료 | C33: 2700000 | D33: 0 | E33: 0 | F33: =C33+D33-E33 -> 2700000 | H33: `
A34: 5263-00-000 | B34: Advertising / 광고비용 | C34: 4505000 | D34: 0 | E34: 0 | F34: =C34+D34-E34 -> 4505000
A35: 5279-00-000 | B35: Other travel, entertainment & social events / 여비교통비 - 기타 | C35: 39000 | D35: 0 | E35: 0 | F35: =C35+D35-E35 -> 39000
A36: 5243-00-000 | B36: Tax consultancy fees / 세금과공과 | C36: 0 | D36: 739540 | E36: 0 | F36: =C36+D36-E36 -> 739540
A37: 7103-00-000 | B37: Other tax expense / 기타 세금과공과 | C37: 55000 | D37: 0 | E37: 0 | F37: =C37+D37-E37 -> 55000
A38: 5281-00-000 | B38: Rent / 지급임차료 | C38: 2000000 | D38: 10472000 | E38: 0 | F38: =C38+D38-E38 -> 12472000
A39: 5301-00-000 | B39: Bank charges / 은행 수수료 | C39: 63876 | D39: 8400 | E39: 0 | F39: =C39+D39-E39 -> 72276
A40: 5319-00-000 | B40: Donations / 기부금 | C40: 20000000 | D40: 0 | E40: 0 | F40: =C40+D40-E40 -> 20000000
...

Sheet JE(5)
A1: Posting Date | B1: 날짜 | C1: Document No. | D1: G/L Account No. | E1: G/L Account Name | F1: Description | G1: Debit Amount (LCY) | H1: Credit Amount (LCY) | I1: Vendor Code
A2: 1/1/2024 | B2: =TEXT(DATE(RIGHT(A2,4),LEFT(A2,FIND("/",A2)-1),MID(A2,FIND("/",A2)+1,FIND("/",A2,FIND("/",A2)+1)-FIND("/",A2)-1)),"yyyy/mm/dd") -> 2024/01/01 | C2: 20241130-1 | D2: 1211-00-000 | E2: Accounts receivables / 외상매출금 | F2: 2023년 확정 (본사직원) 고용보험료 (분할신설법인 부담분) | G2: 36448817 | H2: 0
A3: 1/1/2024 | B3: =TEXT(DATE(RIGHT(A3,4),LEFT(A3,FIND("/",A3)-1),MID(A3,FIND("/",A3)+1,FIND("/",A3,FIND("/",A3)+1)-FIND("/",A3)-1)),"yyyy/mm/dd") -> 2024/01/01 | C3: 20241130-1 | D3: 1211-00-000 | E3: Accounts receivables / 외상매출금 | F3: 2023년 확정 (본사직원) 고용보험료 (분할신설법인 부담분) | G3: 0 | H3: 36448817
A4: 2/1/2024 | B4: =TEXT(DATE(RIGHT(A4,4),LEFT(A4,FIND("/",A4)-1),MID(A4,FIND("/",A4)+1,FIND("/",A4,FIND("/",A4)+1)-FIND("/",A4)-1)),"yyyy/mm/dd") -> 2024/02/01 | C4: 20241130-1 | D4: 2203-00-000 | E4: Intercompany Payable / 관계사미지급금 | F4: IECSG001-INV24-0044 | G4: 0 | H4: 769691
A5: 2/1/2024 | B5: =TEXT(DATE(RIGHT(A5,4),LEFT(A5,FIND("/",A5)-1),MID(A5,FIND("/",A5)+1,FIND("/",A5,FIND("/",A5)+1)-FIND("/",A5)-1)),"yyyy/mm/dd") -> 2024/02/01 | C5: 20241130-1 | D5: 2203-00-000 | E5: Intercompany Payable / 관계사미지급금 | F5: IECSG001-INV24-0044 | G5: 769691 | H5: 0
A6: 3/29/2024 | B6: =TEXT(DATE(RIGHT(A6,4),LEFT(A6,FIND("/",A6)-1),MID(A6,FIND("/",A6)+1,FIND("/",A6,FIND("/",A6)+1)-FIND("/",A6)-1)),"yyyy/mm/dd") -> 2024/03/29 | C6: 20241130-2 | D6: 1211-00-000 | E6: Accounts receivables / 외상매출금 | F6: 2023년 확정 (본사직원) 고용보험료 (분할신설법인 부담분) | G6: 52910 | H6: 0
A7: 3/29/2024 | B7: =TEXT(DATE(RIGHT(A7,4),LEFT(A7,FIND("/",A7)-1),MID(A7,FIND("/",A7)+1,FIND("/",A7,FIND("/",A7)+1)-FIND("/",A7)-1)),"yyyy/mm/dd") -> 2024/03/29 | C7: 20241130-2 | D7: 1211-00-000 | E7: Accounts receivables / 외상매출금 | F7: 2023년 확정 (본사직원) 고용보험료 (분할신설법인 부담분) | G7: 0 | H7: 52910
A8: 3/29/2024 | B8: =TEXT(DATE(RIGHT(A8,4),LEFT(A8,FIND("/",A8)-1),MID(A8,FIND("/",A8)+1,FIND("/",A8,FIND("/",A8)+1)-FIND("/",A8)-1)),"yyyy/mm/dd") -> 2024/03/29 | C8: 20241130-3 | D8: 1211-00-000 | E8: Accounts receivables / 외상매출금 | F8: 2023년 확정 (본사직원) 산재보험료 (분할신설법인 부담분) | G8: 37630 | H8: 0
A9: 3/29/2024 | B9: =TEXT(DATE(RIGHT(A9,4),LEFT(A9,FIND("/",A9)-1),MID(A9,FIND("/",A9)+1,FIND("/",A9,FIND("/",A9)+1)-FIND("/",A9)-1)),"yyyy/mm/dd") -> 2024/03/29 | C9: 20241130-3 | D9: 1211-00-000 | E9: Accounts receivables / 외상매출금 | F9: 2023년 확정 (본사직원) 산재보험료 (분할신설법인 부담분) | G9: 0 | H9: 37630
A10: 5/31/2024 | B10: =TEXT(DATE(RIGHT(A10,4),LEFT(A10,FIND("/",A10)-1),MID(A10,FIND("/",A10)+1,FIND("/",A10,FIND("/",A10)+1)-FIND("/",A10)-1)),"yyyy/mm/dd") -> 2024/05/31 | C10: 20241130-2 | D10: 2203-00-000 | E10: Intercompany Payable / 관계사미지급금 | F10: 1Q Interco Billing | G10: 0 | H10: 141245630
A11: 5/31/2024 | B11: =TEXT(DATE(RIGHT(A11,4),LEFT(A11,FIND("/",A11)-1),MID(A11,FIND("/",A11)+1,FIND("/",A11,FIND("/",A11)+1)-FIND("/",A11)-1)),"yyyy/mm/dd") -> 2024/05/31 | C11: 20241130-2 | D11: 2203-00-000 | E11: Intercompany Payable / 관계사미지급금 | F11: 1Q Interco Billing | G11: 141245630 | H11: 0
A12: 7/1/2024 | B12: =TEXT(DATE(RIGHT(A12,4),LEFT(A12,FIND("/",A12)-1),MID(A12,FIND("/",A12)+1,FIND("/",A12,FIND("/",A12)+1)-FIND("/",A12)-1)),"yyyy/mm/dd") -> 2024/07/01 | C12: 20241130-3 | D12: 2203-00-000 | E12: Intercompany Payable / 관계사미지급금 | F12: 2Q Interco Billing | G12: 0 | H12: 117281772
A13: 7/1/2024 | B13: =TEXT(DATE(RIGHT(A13,4),LEFT(A13,FIND("/",A13)-1),MID(A13,FIND("/",A13)+1,FIND("/",A13,FIND("/",A13)+1)-FIND("/",A13)-1)),"yyyy/mm/dd") -> 2024/07/01 | C13: 20241130-3 | D13: 2203-00-000 | E13: Intercompany Payable / 관계사미지급금 | F13: 2Q Interco Billing | G13: 117281772 | H13: 0
... A160: 12/31/2024 | B160: =TEXT(DATE(RIGHT(A160,4),LEFT(A160,FIND("/",A160)-1),MID(A160,FIND("/",A160)+1,FIND("/",A160,FIND("/",A160)+1)-FIND("/",A160)-1)),"yyyy/mm/dd") -> 2024/12/31 | C160: GJ24-0023 | D160: 2202-00-001 | E160: Other payable / 기타미지급금 | F160: Other legal and professional fees / 기타 법률 및 전문 수수료 | G160: 0 | H160: 715000
A161: 12/31/2024 | B161: =TEXT(DATE(RIGHT(A161,4),LEFT(A161,FIND("/",A161)-1),MID(A161,FIND("/",A161)+1,FIND("/",A161,FIND("/",A161)+1)-FIND("/",A161)-1)),"yyyy/mm/dd") -> 2024/12/31 | C161: GJ24-0026 | D161: 5211-00-000 | E161: Organizational expenses / 관리운용비용 | F161: Organizational expenses / 관리운용비용 | G161: 58318120 | H161: 0 | I161: IECKR001
A162: 12/31/2024 | B162: =TEXT(DATE(RIGHT(A162,4),LEFT(A162,FIND("/",A162)-1),MID(A162,FIND("/",A162)+1,FIND("/",A162,FIND("/",A162)+1)-FIND("/",A162)-1)),"yyyy/mm/dd") -> 2024/12/31 | C162: GJ24-0026 | D162: 2202-00-000 | E162: Accrued liabilities / 계약부채 | F162: Organizational expenses / 관리운용비용 | G162: 0 | H162: 58318120 | I162: IECKR001
A163: 12/31/2024 | B163: =TEXT(DATE(RIGHT(A163,4),LEFT(A163,FIND("/",A163)-1),MID(A163,FIND("/",A163)+1,FIND("/",A163,FIND("/",A163)+1)-FIND("/",A163)-1)),"yyyy/mm/dd") -> 2024/12/31 | C163: GJ24-0027 | D163: 2203-00-000 | E163: Intercompany Payable / 관계사미지급금 | F163: Accrued liabilities / 계약부채 | G163: 0 | H163: 147977176 | I163: IECKR001
A164: 12/31/2024 | B164: =TEXT(DATE(RIGHT(A164,4),LEFT(A164,FIND("/",A164)-1),MID(A164,FIND("/",A164)+1,FIND("/",A164,FIND("/",A164)+1)-FIND("/",A164)-1)),"yyyy/mm/dd") -> 2024/12/31 | C164: GJ24-0027 | D164: 2202-00-000 | E164: Accrued liabilities / 계약부채 | F164: Accrued liabilities / 계약부채 | G164: 147977176 | H164: 0 | I164: IECKR001
A165: 12/31/2024 | B165: =TEXT(DATE(RIGHT(A165,4),LEFT(A165,FIND("/",A165)-1),MID(A165,FIND("/",A165)+1,FIND("/",A165,FIND("/",A165)+1)-FIND("/",A165)-1)),"yyyy/mm/dd") -> 2024/12/31 | C165: GJ24-0028 | D165: 2203-00-000 | E165: Intercompany Payable / 관계사미지급금 | F165: Accrued liabilities / 계약부채 | G165: 1 | H165: 0
A166: 12/31/2024 | B166: =TEXT(DATE(RIGHT(A166,4),LEFT(A166,FIND("/",A166)-1),MID(A166,FIND("/",A166)+1,FIND("/",A166,FIND("/",A166)+1)-FIND("/",A166)-1)),"yyyy/mm/dd") -> 2024/12/31 | C166: GJ24-0028 | D166: 2202-00-000 | E166: Accrued liabilities / 계약부채 | F166: Accrued liabilities / 계약부채 | G166: 0 | H166: 1
A167: 12/31/2024 | B167: =TEXT(DATE(RIGHT(A167,4),LEFT(A167,FIND("/",A167)-1),MID(A167,FIND("/",A167)+1,FIND("/",A167,FIND("/",A167)+1)-FIND("/",A167)-1)),"yyyy/mm/dd") -> 2024/12/31 | C167: GJ24-0029 | D167: 7103-00-000 | E167: Other tax expense / 기타 세금과공과 | F167: Close Income Statement | G167: 0 | H167: 4703720
A168: 12/31/2024 | B168: =TEXT(DATE(RIGHT(A168,4),LEFT(A168,FIND("/",A168)-1),MID(A168,FIND("/",A168)+1,FIND("/",A168,FIND("/",A168)+1)-FIND("/",A168)-1)),"yyyy/mm/dd") -> 2024/12/31 | C168: GJ24-0029 | D168: 5719-00-000 | E168: Interest expense - External / 이자비용 - 일반 | F168: Close Income Statement | G168: 0 | H168: 94634669
A169: 12/31/2024 | B169: =TEXT(DATE(RIGHT(A169,4),LEFT(A169,FIND("/",A169)-1),MID(A169,FIND("/",A169)+1,FIND("/",A169,FIND("/",A169)+1)-FIND("/",A169)-1)),"yyyy/mm/dd") -> 2024/12/31 | C169: GJ24-0029 | D169: 5717-00-000 | E169: Interest expense - InterCo / 이자비용 - 회사 간 대출 | F169: Close Income Statement | G169: 0 | H169: 757260510
A170: 12/31/2024 | B170: =TEXT(DATE(RIGHT(A170,4),LEFT(A170,FIND("/",A170)-1),MID(A170,FIND("/",A170)+1,FIND("/",A170,FIND("/",A170)+1)-FIND("/",A170)-1)),"yyyy/mm/dd") -> 2024/12/31 | C170: GJ24-0029 | D170: 5711-00-000 | E170: ROU Lease - Interest expense / 금융리스 - 이자비용 | F170: Close Income Statement | G170: 0 | H170: 8360655
A171: 12/31/2024 | B171: =TEXT(DATE(RIGHT(A171,4),LEFT(A171,FIND("/",A171)-1),MID(A171,FIND("/",A171)+1,FIND("/",A171,FIND("/",A171)+1)-FIND("/",A171)-1)),"yyyy/mm/dd") -> 2024/12/31 | C171: GJ24-0029 | D171: 5612-00-000 | E171: Interest income - bank / 이자수익 - 은행 | F171: Close Income Statement | G171: 754509 | H171: 0
A172: 12/31/2024 | B172: =TEXT(DATE(RIGHT(A172,4),LEFT(A172,FIND("/",A172)-1),MID(A172,FIND("/",A172)+1,FIND("/",A172,FIND("/",A172)+1)-FIND("/",A172)-1)),"yyyy/mm/dd") -> 2024/12/31 | C172: GJ24-0029 | D172: 5601-00-000 | E172: Other expenses / 잡손실 | F172: Close Income Statement | G172: 0 | H172: 797033
A173: 12/31/2024 | B173: =TEXT(DATE(RIGHT(A173,4),LEFT(A173,FIND("/",A173)-1),MID(A173,FIND("/",A173)+1,FIND("/",A173,FIND("/",A173)+1)-FIND("/",A173)-1)),"yyyy/mm/dd") -> 2024/12/31 | C173: GJ24-0029 | D173: 5342-00-000 | E173: FX - realized loss - others / 외환차손 | F173: Close Income Statement | G173: 0 | H173: 72876
A174: 12/31/2024 | B174: =TEXT(DATE(RIGHT(A174,4),LEFT(A174,FIND("/",A174)-1),MID(A174,FIND("/",A174)+1,FIND("/",A174,FIND("/",A174)+1)-FIND("/",A174)-1)),"yyyy/mm/dd") -> 2024/12/31 | C174: GJ24-0029 | D174: 5318-00-000 | E174: Social events / 행사비 | F174: Close Income Statement | G174: 0 | H174: 2000000
A175: 12/31/2024 | B175: =TEXT(DATE(RIGHT(A175,4),LEFT(A175,FIND("/",A175)-1),MID(A175,FIND("/",A175)+1,FIND("/",A175,FIND("/",A175)+1)-FIND("/",A175)-1)),"yyyy/mm/dd") -> 2024/12/31 | C175: GJ24-0029 | D175: 5301-00-000 | E175: Bank charges / 은행 수수료 | F175: Close Income Statement | G175: 0 | H175: 59500
A176: 12/31/2024 | B176: =TEXT(DATE(RIGHT(A176,4),LEFT(A176,FIND("/",A176)-1),MID(A176,FIND("/",A176)+1,FIND("/",A176,FIND("/",A176)+1)-FIND("/",A176)-1)),"yyyy/mm/dd") -> 2024/12/31 | C176: GJ24-0029 | D176: 5291-00-000 | E176: Telecommunication expenses / 통신비 | F176: Close Income Statement | G176: 0 | H176: 409550
... A180: 12/31/2024 | B180: =TEXT(DATE(RIGHT(A180,4),LEFT(A180,FIND("/",A180)-1),MID(A180,FIND("/",A180)+1,FIND("/",A180,FIND("/",A180)+1)-FIND("/",A180)-1)),"yyyy/mm/dd") -> 2024/12/31 | C180: GJ24-0029 | D180: 5227-SG-002 | E180: Insurance - Employee / 고용 산재보험료 | F180: Close Income Statement | G180: 0 | H180: 436030
A181: 12/31/2024 | B181: =TEXT(DATE(RIGHT(A181,4),LEFT(A181,FIND("/",A181)-1),MID(A181,FIND("/",A181)+1,FIND("/",A181,FIND("/",A181)+1)-FIND("/",A181)-1)),"yyyy/mm/dd") -> 2024/12/31 | C181: GJ24-0029 | D181: 5211-00-000 | E181: Organizational expenses / 관리운용비용 | F181: Close Income Statement | G181: 0 | H181: 58318120 | I181: IECKR001
A182: 12/31/2024 | B182: =TEXT(DATE(RIGHT(A182,4),LEFT(A182,FIND("/",A182)-1),MID(A182,FIND("/",A182)+1,FIND("/",A182,FIND("/",A182)+1)-FIND("/",A182)-1)),"yyyy/mm/dd") -> 2024/12/31 | C182: GJ24-0029 | D182: 5211-00-000 | E182: Organizational expenses / 관리운용비용 | F182: Close Income Statement | G182: 0 | H182: 415073691
A183: 12/31/2024 | B183: =TEXT(DATE(RIGHT(A183,4),LEFT(A183,FIND("/",A183)-1),MID(A183,FIND("/",A183)+1,FIND("/",A183,FIND("/",A183)+1)-FIND("/",A183)-1)),"yyyy/mm/dd") -> 2024/12/31 | C183: GJ24-0029 | D183: 5101-00-000 | E183: Management fee expense / 관리 수수료 비용 | F183: Close Income Statement | G183: 0 | H183: 407440
A184: 12/31/2024 | B184: =TEXT(DATE(RIGHT(A184,4),LEFT(A184,FIND("/",A184)-1),MID(A184,FIND("/",A184)+1,FIND("/",A184,FIND("/",A184)+1)-FIND("/",A184)-1)),"yyyy/mm/dd") -> 2024/12/31 | C184: GJ24-0029 | D184: 4401-00-000 | E184: Other income / 잡이익 | F184: Close Income Statement | G184: 8270 | H184: 0
A185: 12/31/2024 | B185: =TEXT(DATE(RIGHT(A185,4),LEFT(A185,FIND("/",A185)-1),MID(A185,FIND("/",A185)+1,FIND("/",A185,FIND("/",A185)+1)-FIND("/",A185)-1)),"yyyy/mm/dd") -> 2024/12/31 | C185: GJ24-0029 | D185: 3401-00-000 | E185: Retained earnings / 이익 잉여금 | F185: Close Income Statement | G185: 1362082031 | H185: 0
A186: 1/2/2025 | B186: =TEXT(DATE(RIGHT(A186,4),LEFT(A186,FIND("/",A186)-1),MID(A186,FIND("/",A186)+1,FIND("/",A186,FIND("/",A186)+1)-FIND("/",A186)-1)),"yyyy/mm/dd") -> 2025/01/02 | C186: GJ25-0001 | D186: 5301-00-000 | E186: Bank charges / 은행 수수료 | F186: (HTX)_공인인증서(은행/보험용) / 은행 수수료 | G186: 4000 | H186: 0
A187: 1/2/2025 | B187: =TEXT(DATE(RIGHT(A187,4),LEFT(A187,FIND("/",A187)-1),MID(A187,FIND("/",A187)+1,FIND("/",A187,FIND("/",A187)+1)-FIND("/",A187)-1)),"yyyy/mm/dd") -> 2025/01/02 | C187: GJ25-0001 | D187: 2407-00-000 | E187: GST/VAT receivable / 부가세대급금 | F187: (HTX)_공인인증서(은행/보험용) / 부가세대급금 | G187: 400 | H187: 0
A188: 1/2/2025 | B188: =TEXT(DATE(RIGHT(A188,4),LEFT(A188,FIND("/",A188)-1),MID(A188,FIND("/",A188)+1,FIND("/",A188,FIND("/",A188)+1)-FIND("/",A188)-1)),"yyyy/mm/dd") -> 2025/01/02 | C188: GJ25-0001 | D188: 2202-00-001 | E188: Other payable / 기타미지급금 | F188: (HTX)_공인인증서(은행/보험용) / 기타미지급금 | G188: 0 | H188: 4400
A189: 1/2/2025 | B189: =TEXT(DATE(RIGHT(A189,4),LEFT(A189,FIND("/",A189)-1),MID(A189,FIND("/",A189)+1,FIND("/",A189,FIND("/",A189)+1)-FIND("/",A189)-1)),"yyyy/mm/dd") -> 2025/01/02 | C189: GJ25-0002 | D189: 5301-00-000 | E189: Bank charges / 은행 수수료 | F189: [KR Inv_202412] VJIPYON02_Kummyung_Registration fee for debt to equity_KRW 23487000 _ 은행 수수료 | G189: 500 | H189: 0
...

Sheet COA
A1: 계정코드 | B1: 국문명 | C1: 다국어 | D1: 분류 | E1: 코드성격 | F1: 보조계정 | G1: 보조국문명 | H1: 보조국문명 | I1: 사용여부
A2: 1101-00-000 | B2: 현금 - CNY | C2: Cash - CNY | D2: A | E2: ZZ | I2: Y
A3: 1102-00-000 | B3: 현금 - HKD | C3: Cash - HKD | D3: A | E3: ZZ | I3: Y
A4: 1103-00-000 | B4: 현금 - INR | C4: Cash - INR | D4: A | E4: ZZ | I4: Y
A5: 1104-00-000 | B5: 현금 - 엔 | C5: Cash - JPY | D5: A | E5: ZZ | I5: Y
A6: 1105-00-000 | B6: 현금 - PHP | C6: Cash - PHP | D6: A | E6: ZZ | I6: Y
A7: 1106-00-000 | B7: 현금 - SGD | C7: Cash - SGD | D7: A | E7: ZZ | I7: Y
A8: 1107-00-000 | B8: 현금 - THB | C8: Cash - THB | D8: A | E8: ZZ | I8: Y
A9: 1108-00-000 | B9: 현금 - USD | C9: Cash - USD | D9: A | E9: ZZ | I9: Y
A10: 1108-00-001 | B10: 현금 - USD (HSBC) | C10: Cash - USD (HSBC) | D10: A | E10: ZZ | I10: Y
A11: 1108-00-002 | B11: 현금 - USD (스탠다드차타드) | C11: Cash - USD (Standard Chartered) | D11: A | E11: ZZ | I11: Y
A12: 1108-KR-001 | B12: 현금 - USD (HANA) | C12: Cash - USD (HANA) | D12: A | E12: ZZ | I12: Y
A13: 1108-KR-002 | B13: 현금 - USD (HSBC) | C13: Cash - USD (HSBC) | D13: A | E13: ZZ | I13: Y
... A532: 9902-00-000 | B532: 아메리칸 익스프레스 법인 카드 클리어링 계정 | C532: American Express Corporate Card Clearing Account | D532: L | E532: ZZ | I532: Y

Sheet 잔액명세서
C2: BS 거래처별 잔액명세서
C3: 금명 유한회사
C4: 2025/01/31 ~ 2025/02/28
A5: =IF(C5="",A4,C5) -> 계정 | B5: =IF(D5="",B4,D5) -> 계정명 | C5: 계정 | D5: 계정명 | E5: 거래처코드 | G5: 거래처명 | I5: 2025/01/31 | J5: 2025/02/28
A6: =IF(C6="",A5,C6) -> 자산 | B6: =IF(D6="",B5,D6) -> 계정명 | C6: 자산
A7: =IF(C7="",A6,C7) -> 1112-KR-001 | B7: =IF(D7="",B6,D7) -> 현금 - 원 (HANA) | C7: 1112-KR-001 | D7: 현금 - 원 (HANA) | E7: 201-910031-85704 | G7: HANA_Bank 하나은행(85704) | I7: 325492654 | J7: 2106438696
A8: =IF(C8="",A7,C8) -> 1112-KR-001 | B8: =IF(D8="",B7,D8) -> 현금 - 원 (HANA) | C8: 1112-KR-001 | I8: 325492654 | J8: 2106438696
A9: =IF(C9="",A8,C9) -> 1112-KR-005 | B9: =IF(D9="",B8,D9) -> 현금 - 원 (신협) | C9: 1112-KR-005 | D9: 현금 - 원 (신협) | E9: 131-022-007238 | G9: 신협 (007238) | I9: 28229508 | J9: 20448685
A10: =IF(C10="",A9,C10) -> 1112-KR-005 | B10: =IF(D10="",B9,D10) -> 현금 - 원 (신협) | C10: 1112-KR-005 | I10: 28229508 | J10: 20448685
A11: =IF(C11="",A10,C11) -> 1212-00-000 | B11: =IF(D11="",B10,D11) -> 선납세금 | C11: 1212-00-000 | D11: 선납세금 | E11: 4617043000 | G11: Naju Districted Office_나주시청 | I11: 21560 | J11: 21560
A12: =IF(C12="",A11,C12) -> 1212-00-000 | B12: =IF(D12="",B11,D12) -> 선납세금 | E12: TAX412 | G12: Naju Tax Office 나주세무서 | I12: 215870 | J12: 215870
A13: =IF(C13="",A12,C13) -> 1212-00-000 | B13: =IF(D13="",B12,D13) -> 선납세금 | C13: 1212-00-000 | I13: 237430 | J13: 237430
A14: =IF(C14="",A13,C14) -> 1214-00-000 | B14: =IF(D14="",B13,D14) -> 기타미수금 | C14: 1214-00-000 | D14: 기타미수금 | E14: 4808102805 | G14: 주시회사 금명건설 | I14: 36539357 | J14: 36539357
A15: =IF(C15="",A14,C15) -> 1214-00-000 | B15: =IF(D15="",B14,D15) -> 기타미수금 | E15: TAX412 | G15: Naju Tax Office 나주세무서 | I15: 22046685 | J15: 0
A16: =IF(C16="",A15,C16) -> 1214-00-000 | B16: =IF(D16="",B15,D16) -> 기타미수금 | C16: 1214-00-000 | I16: 58586042 | J16: 36539357
A17: =IF(C17="",A16,C17) -> 1231-00-000 | B17: =IF(D17="",B16,D17) -> 임차보증금 - 비유동 | C17: 1231-00-000 | D17: 임차보증금 - 비유동 | E17: 1168268413 | G17: 세정아울렛 관리단 | I17: 980000 | J17: 980000
A18: =IF(C18="",A17,C18) -> 1231-00-000 | B18: =IF(D18="",B17,D18) -> 임차보증금 - 비유동 | E18: 1608101862 | G18: 유한회사 삼형 | I18: 20000000 | J18: 20000000
A19: =IF(C19="",A18,C19) -> 1231-00-000 | B19: =IF(D19="",B18,D19) -> 임차보증금 - 비유동 | C19: 1231-00-000 | I19: 20980000 | J19: 20980000
A20: =IF(C20="",A19,C20) -> 1232-00-000 | B20: =IF(D20="",B19,D20) -> 선급비용 | C20: 1232-00-000 | D20: 선급비용 | E20: 1608101862 | G20: 유한회사 삼형 | I20: 10000000 | J20: 9000000
A21: =IF(C21="",A20,C21) -> 1232-00-000 | B21: =IF(D21="",B20,D21) -> 선급비용 | C21: 1232-00-000 | I21: 10000000 | J21: 9000000
A22: =IF(C22="",A21,C22) -> 1233-00-000 | B22: =IF(D22="",B21,D22) -> 선급금 (유동) | C22: 1233-00-000 | D22: 선급금 (유동) | E22: 2208711247 | G22: 삼정 KPMG AAS (proxy payment) | I22: 43834 | J22: 0
A23: =IF(C23="",A22,C23) -> 1233-00-000 | B23: =IF(D23="",B22,D23) -> 선급금 (유동) | C23: 1233-00-000 | I23: 43834 | J23: 0
A24: =IF(C24="",A23,C24) -> 1712-00-000 | B24: =IF(D24="",B23,D24) -> 토지 | C24: 1712-00-000 | D24: 토지 | I24: 3016419000 | J24: 3016419000
A25: =IF(C25="",A24,C25) -> 1712-00-000 | B25: =IF(D25="",B24,D25) -> 토지 | E25: 1546700144 | G25: 법무사정찬선 사무소 | I25: 7730646 | J25: 7730646
A26: =IF(C26="",A25,C26) -> 1712-00-000 | B26: =IF(D26="",B25,D26) -> 토지 | E26: 4110279147 | G26: 김윤석 법무사 | I26: 10739760 | J26: 10739760
A27: =IF(C27="",A26,C27) -> 1712-00-000 | B27: =IF(D27="",B26,D27) -> 토지 | E27: 4118183990 | G27: (유)늘샘쏠라에너지 | I27: 2692540000 | J27: 2944540000
A28: =IF(C28="",A27,C28) -> 1712-00-000 | B28: =IF(D28="",B27,D28) -> 토지 | E28: 4118202510 | G28: 목포신용협동조합 | I28: 44432873 | J28: 44432873
A29: =IF(C29="",A28,C29) -> 1712-00-000 | B29: =IF(D29="",B28,D29) -> 토지 | E29: 4617043000 | G29: Naju Districted Office_나주시청 | I29: 262060100 | J29: 262060100
A30: =IF(C30="",A29,C30) -> 1712-00-000 | B30: =IF(D30="",B29,D30) -> 토지 | E30: 4691025300 | G30: Sinan Districted Office_신안군청 | I30: 552000 | J30: 552000
A31: =IF(C31="",A30,C31) -> 1712-00-000 | B31: =IF(D31="",B30,D31) -> 토지 | E31: 5438101960 | G31: 법무사법인 목포 | I31: 3880100 | J31: 3880100
A32: =IF(C32="",A31,C32) -> 1712-00-000 | B32: =IF(D32="",B31,D32) -> 토지 | E32: 5571701838 | G32: 법무사이형오사무소 | I32: 4683230 | J32: 4683230
A33: =IF(C33="",A32,C33) -> 1712-00-000 | B33: =IF(D33="",B32,D33) -> 토지 | E33: 5998701228 | G33: ㈜삼정개발 | I33: 155971200 | J33: 155971200
A34: =IF(C34="",A33,C34) -> 1712-00-000 | B34: =IF(D34="",B33,D34) -> 토지 | E34: 8258101824 | G34: EEK 2 에퀴스에너지코리아2 유한회사 | I34: 583660095 | J34: 583660095
A35: =IF(C35="",A34,C35) -> 1712-00-000 | B35: =IF(D35="",B34,D35) -> 토지 | C35: 1712-00-000 | I35: 6782669004 | J35: 7034669004
A36: =IF(C36="",A35,C36) -> 2407-00-000 | B36: =IF(D36="",B35,D36) -> 부가세대급금 | C36: 2407-00-000 | D36: 부가세대급금 | E36: 1028134334 | G36: KPMG 삼정회계법인 | I36: 140000 | J36: 205000
