Workbook
Name TB: #REF!
Name TB: #REF!
Name TB: #REF!
Name TB: #REF!
Name TBV: #REF!
Name TBV: #REF!
Name TBV: #REF!
Name TBV: #REF!
Name UFPrn20060929121919: #REF!
Name UFPrn20060929121919: #REF!
Name UFPrn20060929121919: #REF!
Name UFPrn20060929121919: #REF!
Name UFPrn20060929122307: #REF!
Name UFPrn20060929122307: #REF!
Name UFPrn20060929122307: #REF!
Name UFPrn20060929122307: #REF!
Name UFPrn20060929153427: #REF!
Name UFPrn20060929153427: #REF!
Name UFPrn20060929153427: #REF!
Name UFPrn20060929153427: #REF!
Name UFPrn20061101172252: #REF!
Name UFPrn20061101172252: #REF!
Name UFPrn20061101172252: #REF!
Name UFPrn20061101172252: #REF!
Name UFPrn20071206135312: #REF!
Name UFPrn20071206135312: #REF!
Name UFPrn20071206135312: #REF!
Name UFPrn20071206135312: #REF!
Name UFPrn20071206163429: #REF!
Name UFPrn20071206163429: #REF!
Name UFPrn20071206163429: #REF!
Name UFPrn20071206163429: #REF!
Name UFPrn20071206164549: #REF!
Name UFPrn20071206164549: #REF!
Name UFPrn20071206164549: #REF!
Name UFPrn20071206164549: #REF!
Name UFPrn20071206164935: #REF!
Name UFPrn20071206164935: #REF!
Name UFPrn20071206164935: #REF!
Name UFPrn20071206164935: #REF!
Name UFPrn20071206185711: #REF!
Name UFPrn20071206185711: #REF!
Name UFPrn20071206185711: #REF!
Name UFPrn20071206185711: #REF!
Name UFPrn20080121112404: #REF!
Name UFPrn20080121112404: #REF!
Name UFPrn20080121112404: #REF!
Name UFPrn20080121112404: #REF!
Name 核算项目分类总账: #REF!
Name 核算项目分类总账: #REF!
Name 核算项目分类总账: #REF!
Name 核算项目分类总账: #REF!
Name 会计分录序时簿: #REF!
Name 会计分录序时簿: #REF!
Name 会计分录序时簿: #REF!
Name 会计分录序时簿: #REF!

Sheet Jan–Apr 2026 Summary
D2: AVERAGE RATE | E2: 1454.9022 | F2: AVERAGE RATE | G2: 1448.4907 | H2: AVERAGE RATE | I2: 1488.4736 | J2: AVERAGE RATE | K2: 1485.7594
A3: Account Name | B3: EY code | C3: Qatar code | D3: 2026.01 | F3: 2026.02 | H3: 2026.03 | J3: 2026.04
D4: KRW | E4: USD | F4: KRW | G4: USD | H4: KRW | I4: USD | J4: KRW | K4: USD
A5: Ⅳ. S/A expenses | B5: total | D5: =SUM(D6:D26) -> 249666113 | E5: =SUM(E6:E26) -> 171603.36 | F5: =SUM(F6:F26) -> 252898961 | G5: =SUM(G6:G26) -> 174594.81 | H5: =SUM(H6:H26)+H37 -> 213138159 | I5: =SUM(I6:I26) -> 136524.28 | J5: =SUM(J6:J26) -> 562762576 | K5: =SUM(K6:K26) -> 378771
A6: [80200] Employee wages and salaries | B6: 80200 | C6: 571001 | D6: 43747569 | E6: =D6/$E$2 -> 30069.079 | F6: 46013633 | G6: =F6/$G$2 -> 31766.606 | H6: 44880601 | I6: =H6/$I$2 -> 30152.097 | J6: 84534804 | K6: =J6/$K$2 -> 56896.698
A7: [80300] Bonuses | B7: 80300 | C7: 571001 | D7: 0 | E7: =D7/$E$2 -> 0 | F7: 67897463 | G7: =F7/$G$2 -> 46874.628 | H7: 0 | I7: =H7/$I$2 -> 0 | J7: 0 | K7: =J7/$K$2 -> 0
A8: [80800] Retirement benefits | B8: 80800 | C8: 571001 | D8: 0 | E8: =D8/$E$2 -> 0 | F8: 0 | G8: =F8/$G$2 -> 0 | I8: =H8/$I$2 -> 0 | J8: 325339425 | K8: =J8/$K$2 -> 218971.81
A9: [81100] Employee benefits | B9: 81100 | C9: 702020 | D9: 5000000 | E9: =D9/$E$2 -> 3436.6571 | F9: 5000000 | G9: =F9/$G$2 -> 3451.8689 | H9: 5046500 | I9: =H9/$I$2 -> 3390.386 | J9: 7760191 | K9: =J9/$K$2 -> 5223.0469
A10: [81101] Social Insurance Contributions | B10: 81101 | C10: 571001 | D10: 6960000 | E10: =D10/$E$2 -> 4783.8267 | F10: 4203550 | G10: =F10/$G$2 -> 2902.0207 | H10: 4183160 | I10: =H10/$I$2 -> 2810.369 | J10: 3864230 | K10: =J10/$K$2 -> 2600.8451
A11: [81200] Travel expenses | B11: 81200 | C11: 710600 | D11: 10496250 | E11: =D11/$E$2 -> 7214.4025 | F11: 0 | G11: =F11/$G$2 -> 0 | H11: 0 | I11: =H11/$I$2 -> 0 | J11: 351400 | K11: =J11/$K$2 -> 236.51205
A12: [81300] Entertainment expenses | B12: 81300 | C12: 710500 | D12: 330000 | E12: =D12/$E$2 -> 226.81937 | F12: 0 | G12: =F12/$G$2 -> 0 | H12: 0 | I12: =H12/$I$2 -> 0 | J12: 0 | K12: =J12/$K$2 -> 0
A13: [81400] Communication expenses | B13: 81400 | C13: 710240 | D13: 162464 | E13: =D13/$E$2 -> 111.66661 | F13: 220735 | G13: =F13/$G$2 -> 152.38966 | H13: 159799 | I13: =H13/$I$2 -> 107.35763 | J13: 166125 | K13: =J13/$K$2 -> 111.81151
A14: [81600] Electricity | B14: 81600 | C14: 710210 | D14: 1181490 | E14: =D14/$E$2 -> 812.0752 | F14: 1030420 | G14: =F14/$G$2 -> 711.37495 | H14: 1299120 | I14: =H14/$I$2 -> 872.78673 | J14: 1359580 | K14: =J14/$K$2 -> 915.07414
A15: [81601] GM Housing Utility Fee | B15: 81601 | C15: 702040 | D15: 461810 | E15: =D15/$E$2 -> 317.41652 | F15: 432895 | G15: =F15/$G$2 -> 298.85936 | H15: 624654 | I15: =H15/$I$2 -> 419.66079 | J15: 490079 | K15: =J15/$K$2 -> 329.85085
A16: [81700] Taxes and dues | B16: 81700 | C16: 765030 | D16: 0 | E16: =D16/$E$2 -> 0 | F16: 0 | G16: =F16/$G$2 -> 0 | H16: 0 | I16: =H16/$I$2 -> 0 | J16: 0 | K16: =J16/$K$2 -> 0
A17: [81900] Rental expenses | B17: 81900 | C17: 710200 | D17: 11126890 | E17: =D17/$E$2 -> 7647.8611 | F17: 11126890 | G17: =F17/$G$2 -> 7681.7131 | H17: 36246290 | I17: =H17/$I$2 -> 24351.315 | J17: 36246290 | K17: =J17/$K$2 -> 24395.801
A18: [81902] Equipment Hire Rental | B18: 81902 | C18: 661050 | D18: 49909 | E18: =D18/$E$2 -> 34.304024 | F18: 49909 | G18: =F18/$G$2 -> 34.455865 | H18: 49909 | I18: =H18/$I$2 -> 33.530323 | J18: 49909 | K18: =J18/$K$2 -> 33.591576
A19: [82100] Insurance premium | B19: 82100 | C19: 703007 | D19: 519606 | E19: =D19/$E$2 -> 357.14153 | F19: 519598 | G19: =F19/$G$2 -> 358.71684 | H19: 517348 | I19: =H19/$I$2 -> 347.56948 | J19: 517348 | K19: =J19/$K$2 -> 348.20443
A20: [82200] Vehicles maintenance expenses | B20: 82200 | C20: 643000 | D20: 5071000 | E20: =D20/$E$2 -> 3485.4576 | F20: 5116800 | G20: =F20/$G$2 -> 3532.5046 | H20: 5073000 | I20: =H20/$I$2 -> 3408.1894 | J20: 5359000 | K20: =J20/$K$2 -> 3606.9097
... A26: [83102] Bank Charges | B26: 83102 | C26: 701010 | D26: 1600 | E26: =D26/$E$2 -> 1.0997303 | F26: 3600 | G26: =F26/$G$2 -> 2.4853456 | H26: 6400 | I26: =H26/$I$2 -> 4.2997068 | J26: 9600 | K26: =J26/$K$2 -> 6.4613423
A27: Ⅴ. Operating loss
A28: Ⅵ. N/operating income | B28: total | D28: 0 | F28: 30014
A29: [90100] Interest revenues | B29: 90100 | C29: 990010 | D29: 0 | F29: 0 | H29: 76659 | J29: 0
A30: [90700] Gains on foreign currency transaction | B30: 90700 | C30: 701030 | D30: 0 | F30: 30000 | H30: 0 | J30: 0
A31: [91000] Foreign Exchange Gain | B31: 91000 | C31: 701030 | D31: 0 | F31: 14 | H31: 101030 | J31: -50890
A32: [93000] Miscellaneous revenues | B32: 93000 | C32: 990010 | H32: 22 | J32: 7
A33: Ⅶ. N/operating expenses | B33: total | D33: 0 | F33: 8752811 | H33: 0
A34: [93200] Foreign Exchange Loss | B34: 93200 | C34: 701030 | D34: 0 | F34: 8752811 | H34: 0 | J34: 0
A35: Ⅷ. Net loss before corporate tax
A36: Ⅸ. Corporate tax etc | B36: total | D36: 0 | F36: 0 | H36: 9925370
A37: [99800] Corporate tax etc | B37: 99800 | C37: 765030 | D37: 0 | F37: 0 | H37: 9925370 | I37: =H37/$I$2 -> 6668.1532 | J37: 0
C39: Total Cost | D39: =SUM(D6:D26) -> 249666113 | E39: =SUM(E6:E26) -> 171603.36 | F39: =SUM(F6:F26) -> 252898961 | G39: =SUM(G6:G26) -> 174594.81 | H39: =SUM(H6:H26)+H37 -> 213138159 | I39: =SUM(I6:I26)+I37 -> 143192.43 | J39: =SUM(J6:J26) -> 562762576 | K39: =SUM(K6:K26) -> 378771
C40: Add Markup 6% | D40: =D39*0.06 -> 14979967 | E40: =E39*0.06 -> 10296.202 | F40: =F39*0.06 -> 15173938 | G40: =G39*0.06 -> 10475.689 | H40: =H39*0.06 -> 12788290 | I40: =I39*0.06 -> 8591.5461 | J40: =J39*0.06 -> 33765755 | K40: =K39*0.06 -> 22726.26
C42: Revenue | D42: =D39+D40 -> 2.6464608e+08 | E42: =E39+E40 -> 181899.57 | F42: =F39+F40 -> 2.680729e+08 | G42: =G39+G40 -> 185070.5 | H42: =H39+H40 -> 2.2592645e+08 | I42: =I39+I40 -> 151783.98 | J42: =J39+J40 -> 5.9652833e+08 | K42: =K39+K40 -> 401497.26
B44: Waqas | C44: Total Cost | D44: =E44*$E$2 -> 2.4929044e+08 | E44: 171345.15 | F44: =G44*$G$2 -> 2.5204998e+08 | G44: 174008.7 | H44: =I44*$I$2 -> 2.1442861e+08 | I44: 144059.39 | J44: =K44*$K$2 -> 5.5881117e+08 | K44: 376111.48
C45: Add Markup 6% | D45: =E45*$E$2 -> 14957426 | E45: 10280.709 | F45: =G45*$G$2 -> 15122999 | G45: 10440.522 | H45: =I45*$I$2 -> 12865716 | I45: 8643.5637 | J45: =K45*$K$2 -> 33528670 | K45: 22566.689
C47: Revenue | D47: =D44+D45 -> 2.6424787e+08 | E47: =E44+E45 -> 181625.86 | F47: =F44+F45 -> 2.6717298e+08 | G47: =G44+G45 -> 184449.22 | H47: =H44+H45 -> 2.2729432e+08 | I47: =I44+I45 -> 152702.96 | J47: =J44+J45 -> 5.9233984e+08 | K47: =K44+K45 -> 398678.17
C49: Expense Differ | E49: =E39-E44 -> 258.21096 | G49: =G39-G44 -> 586.11373 | I49: =I39-I44 -> -866.95983 | K49: =K39-K44 -> 2659.5195
C50: Revenue / Cost recoveries Differ | E50: =E42-E47 -> 273.70361 | G50: =G42-G47 -> 621.28056 | I50: =I42-I47 -> -918.97742 | K50: =K42-K47 -> 2819.0907
C52: Invoice already issued | E52: 181625.86 | G52: 184449.22 | I52: 152702.96 | K52: 166569.98
...

Sheet Revenue Markup Working Jan
A1: QATAR ENERGY Seoul, LLC
A2: Income : cost plus mark up 6%
A3: As at 31 January 2026
D4: 1454.9022
A6: Account Code | B6: Description | C6: Korea | D6: YTD -Amounts USD | E6: PL
A7: 80200 | B7: Salaries and wages expense | C7: 급여 및 임금 | D7: 30069.08 | E7: =_xlfn.XLOOKUP(A7,'Jan–Apr 2026 Summary'!B:B,'Jan–Apr 2026 Summary'!E:E) -> 30069.079 | F7: =D7-E7 -> 0.00064069012
A8: 81100 | B8: Employee benefits expense | C8: 종업원 복리후생비 | D8: 3436.6572 | E8: =_xlfn.XLOOKUP(A8,'Jan–Apr 2026 Summary'!B:B,'Jan–Apr 2026 Summary'!E:E) -> 3436.6571 | F8: =D8-E8 -> 7.3225797e-05
A9: 81101 | B9: Social security expense | C9: 사회보험료 | D9: 4783.8268 | E9: =_xlfn.XLOOKUP(A9,'Jan–Apr 2026 Summary'!B:B,'Jan–Apr 2026 Summary'!E:E) -> 4783.8267 | F9: =D9-E9 -> 0.00010193031
A10: 81200 | B10: Travel expense | C10: 출장비 | D10: 10429.239 | E10: =_xlfn.XLOOKUP(A10,'Jan–Apr 2026 Summary'!B:B,'Jan–Apr 2026 Summary'!E:E)+3312.94 -> 10527.342 | F10: =D10-E10 -> -98.103069
A11: 81300 | B11: Entertainment expense | C11: 접대비 | D11: 206.19943 | E11: =_xlfn.XLOOKUP(A11,'Jan–Apr 2026 Summary'!B:B,'Jan–Apr 2026 Summary'!E:E) -> 226.81937 | F11: =D11-E11 -> -20.619938
A12: 81400 | B12: Communication expense | C12: 통신비 | D12: 111.66661 | E12: =_xlfn.XLOOKUP(A12,'Jan–Apr 2026 Summary'!B:B,'Jan–Apr 2026 Summary'!E:E) -> 111.66661 | F12: =D12-E12 -> 2.3793112e-06
A13: 81600 | B13: Utilities expense | C13: 공과금 | D13: 345.07475 | E13: =812.075203405425+316.56-783.56 -> 345.0752 | F13: =D13-E13 -> -0.00045494651
A14: 81601 | B14: Staff housing utilities | C14: 임직원 숙소 공과금 | D14: 0.8591643 | E14: 0.86 | F14: =D14-E14 -> -0.00083570247
A15: 81900 | B15: Short‑term lease / rent expense | C15: 단기 임차료 / 임대료 | D15: 7647.8613 | E15: =_xlfn.XLOOKUP(A15,'Jan–Apr 2026 Summary'!B:B,'Jan–Apr 2026 Summary'!E:E) -> 7647.8611 | F15: =D15-E15 -> 0.00016295508
A16: 81902 | B16: Equipment rental expense | C16: 장비 임차료 | D16: 34.304025 | E16: =_xlfn.XLOOKUP(A16,'Jan–Apr 2026 Summary'!B:B,'Jan–Apr 2026 Summary'!E:E) -> 34.304024 | F16: =D16-E16 -> 7.3092526e-07
A17: 82100 | B17: Insurance expense | C17: 보험료 | D17: 357.14154 | E17: =_xlfn.XLOOKUP(A17,'Jan–Apr 2026 Summary'!B:B,'Jan–Apr 2026 Summary'!E:E) -> 357.14153 | F17: =D17-E17 -> 7.6097127e-06
A18: 82200 | B18: Vehicle maintenance expense | C18: 차량 유지비 | D18: 172.52019 | E18: =_xlfn.XLOOKUP(A18,'Jan–Apr 2026 Summary'!B:B,'Jan–Apr 2026 Summary'!E:E)-3312.94 -> 172.51765 | F18: =D18-E18 -> 0.0025429999
A19: 82300 | B19: Cleaning & Maintainence | C19: 청소 및 시설유지비 | D19: 783.55784 | E19: 783.56 | F19: =D19-E19 -> -0.002160655
A20: 82400 | B20: Freight and logistics expense | C20: 운송 및 물류비 | D20: 60.114008 | E20: =_xlfn.XLOOKUP(A20,'Jan–Apr 2026 Summary'!B:B,'Jan–Apr 2026 Summary'!E:E) -> 199.60792 | F20: =D20-E20 -> -139.49391
A21: 83000 | B21: Office supplies expense | C21: 사무용품비 | D21: 1.3746629 | E21: 1.37 | F21: =D21-E21 -> 0.004662876
A22: 83100 | B22: Professional fees | C22: 외주용역비 / 전문가 수수료 | D22: 0 | E22: 0 | F22: =D22-E22 -> 0
A23: 83102 | B23: Bank charges | C23: 은행수수료 | D23: 1.0997303 | E23: =_xlfn.XLOOKUP(A23,'Jan–Apr 2026 Summary'!B:B,'Jan–Apr 2026 Summary'!E:E) -> 1.0997303 | F23: =D23-E23 -> 2.3432255e-08
A24: 83101 | B24: Staff secondment cost | C24: 파견 인력 비용 | D24: 112755.69 | E24: =_xlfn.XLOOKUP(A24,'Jan–Apr 2026 Summary'!B:B,'Jan–Apr 2026 Summary'!E:E) -> 112755.69 | F24: =D24-E24 -> 0.0024025165
A25: 83103 | B25: Dues & Subscriptions | C25: 회비 및 구독료 | D25: 148.88286 | E25: 148.88 | F25: =D25-E25 -> 0.0028627899
B26: Total Cost | D26: =SUM(D7:D25) -> 171345.15 | E26: =SUM(E7:E25) -> 171603.36 | F26: =SUM(F7:F25) -> -258.20691
B27: Add Markup 6% | D27: =D26*0.06 -> 10280.709 | E27: =E26*0.06 -> 10296.202 | F27: =D27-E27 -> -15.492415
B29: Revenue / Cost recoveries | D29: =D26+D27 -> 181625.86 | E29: =E26+E27 -> 181899.56 | F29: =D29-E29 -> -273.69932
D30: =D29*$D$4 -> 2.6424787e+08 | E30: =E29*$D$4 -> 2.6464607e+08
A33: Co Code | B33: Reference | C33: Doc. Type | D33: Document Date | E33: Posting Date | F33: Posting Period | G33: Doc. HeaderText | H33: Reversal Date | I33: Doc Currency | J33: Pstky | K33: Local Account | L33: Pymt Term | M33: Amount In Doc Curr(USD) | N33: Amount In Local Curr(KRW) | O33: Amt in 2nd Curr | P33: Cost Center | Q33: Profit Center | R33: Value Date | S33: Assignment | T33: Line Item Text | U33: Ref Key 1 | V33: Ref Key 2 | W33: Ref Key 3
A34: 4 CHAR | B34: 16 CHAR | C34: 2 CHAR | D34: 31.12.2023 | E34: 31.12.2023 | F34: 2 CHAR | G34: 25 CHAR | H34: - | I34: 5 CHAR | J34: 2 CHAR | P34: 10 CHAR | Q34: 10 CHAR | R34: - | S34: 18 CHAR | T34: 50 CHAR | U34: 12 CHAR | V34: 12 CHAR | W34: 20 CHAR
A35: 00001 | B35: Qatar Energy Seoul Office | C35: SA | D35: 1.21.2026 | E35: 1.21.2026 | F35: 03 | G35: January Closing_2026 | I35: USD | J35: 50 | K35: 25300 | L35: Non-trade payables | M35: -226.81937 | N35: -330000 | R35: 1.21.2026 | S35: BS14 | T35: Air Support Services(Nexus Jet Co., Ltd.) | U35: JV260100005
A36: 00001 | B36: Qatar Energy Seoul Office | C36: SA | D36: 1.21.2026 | E36: 1.21.2026 | F36: 03 | G36: January Closing_2026 | I36: USD | J36: 40 | K36: 81300 | L36: Entertainment expense | M36: 206.19943 | N36: 300000 | R36: 1.21.2026 | S36: PL10 | T36: Air Support Services(Nexus Jet Co., Ltd.) | U36: JV260100005
A37: 00001 | B37: Qatar Energy Seoul Office | C37: SA | D37: 1.21.2026 | E37: 1.21.2026 | F37: 03 | G37: January Closing_2026 | I37: USD | J37: 40 | K37: 13500 | L37: Value added taxReceivable | M37: 20.619943 | N37: 30000 | R37: 1.21.2026 | S37: BS3 | T37: Air Support Services VAT (Nexus Jet Co., Ltd.) | U37: JV260100005
A38: 50001 | B38: Qatar Energy Seoul Office | C38: SA | D38: 1.25.2026 | E38: 1.25.2026 | F38: 03 | G38: January Closing_2026 | I38: USD | J38: 40 | K38: 25300 | L38: Non-trade payables | M38: -1079.1104 | N38: -1570000 | R38: 1.25.2026 | S38: BS8 | T38: Room 222-4067 G80 (G) 3.5T 19"A (Hyper Silver)/SDS2+ECS 4WD AT (Lotte Rental Co., Ltd.) | U38: JV260100007
A39: 50001 | B39: Qatar Energy Seoul Office | C39: SA | D39: 1.25.2026 | E39: 1.25.2026 | F39: 03 | G39: January Closing_2026 | I39: USD | J39: 40 | K39: 13500 | L39: Value added taxReceivable | M39: 98.100754 | N39: 142727 | R39: 1.25.2026 | S39: PL8 | T39: VAT | U39: JV260100007
A40: 50001 | B40: Qatar Energy Seoul Office | C40: SA | D40: 1.25.2026 | E40: 1.25.2026 | F40: 03 | G40: January Closing_2026 | I40: USD | J40: 50 | K40: 81200 | L40: Travel expense | M40: 981.0096 | N40: 1427273 | R40: 1.25.2026 | S40: BS11 | T40: Room 222-4067 G80 (G) 3.5T 19"A (Hyper Silver)/SDS2+ECS 4WD AT (Lotte Rental Co., Ltd.) | U40: JV260100007
A41: 00001 | B41: Qatar Energy Seoul Office | C41: SA | D41: 1.27.2026 | E41: 1.27.2026 | F41: 05 | G41: January Closing_2026 | I41: USD | J41: 50 | K41: 25300 | L41: Non-trade payables | M41: 139.49392 | N41: 202950 | R41: 1.27.2026 | S41: BS7 | T41: DHL Delivery (Jan 2026)(HANA BANK KRW(24104)) | U41: PV260100017
A42: 00002 | B42: Qatar Energy Seoul Office | C42: SA | D42: 1.27.2026 | E42: 1.27.2026 | F42: 05 | G42: January Closing_2026 | I42: USD | J42: 40 | K42: 10302 | L42: HANA BANK KR KRW CLRG CURRENT (24104) | M42: -139.49392 | N42: -202950 | R42: 1.27.2026 | S42: PL13 | T42: DHL Delivery (Jan 2026) | U42: PV260100017
A45: 81300 | B45: =-M37 -> -20.619943 | C45: *VAT (code 135) is not deductible for entertainment expenses (81300).
A46: 81200 | B46: =-M39 -> -98.100754 | C46: *The input VAT (135) for this vehicle is non-deductible due to vehicle-related restrictions and is processed as disallowed input VAT on a monthly basis.
...

Sheet Revenue Markup Working Feb
A1: QATAR ENERGY Seoul, LLC
A2: Income : cost plus mark up 6%
A3: As at 28 February 2026
D4: 1448.4907
A6: Account Code | B6: Description | D6: YTD -Amounts USD | E6: PL
A7: 80200 | B7: Salaries and wages expense | C7: 급여 및 임금 | D7: 31766.605 | E7: =_xlfn.XLOOKUP(A7,'Jan–Apr 2026 Summary'!B:B,'Jan–Apr 2026 Summary'!G:G) -> 31766.606 | F7: =D7-E7 -> -0.00057020161
A8: 81110 | B8: Bonus | C8: 상여금 | D8: 46874.627 | E8: 46874.628 | F8: =D8-E8 -> -0.00084138635
A9: 81100 | B9: Employee benefits expense | C9: 종업원 복리후생비 | D9: 3462.46 | E9: =_xlfn.XLOOKUP(A9,'Jan–Apr 2026 Summary'!B:B,'Jan–Apr 2026 Summary'!G:G) -> 3451.8689 | F9: =D9-E9 -> 10.591108
A10: 81101 | B10: Social security expense | C10: 사회보험료 | D10: 2113.0408 | E10: =_xlfn.XLOOKUP(A10,'Jan–Apr 2026 Summary'!B:B,'Jan–Apr 2026 Summary'!G:G) -> 2902.0207 | F10: =D10-E10 -> -788.97991
A11: 81200 | B11: Travel expense | C11: 출장비 | D11: 0 | E11: =_xlfn.XLOOKUP(A11,'Jan–Apr 2026 Summary'!B:B,'Jan–Apr 2026 Summary'!G:G) -> 0 | F11: =D11-E11 -> 0
A12: 81300 | B12: Entertainment expense | C12: 접대비 | D12: 0 | E12: =_xlfn.XLOOKUP(A12,'Jan–Apr 2026 Summary'!B:B,'Jan–Apr 2026 Summary'!G:G) -> 0 | F12: =D12-E12 -> 0
A13: 81400 | B13: Communication expense | C13: 통신비 | D13: 152.38965 | E13: =_xlfn.XLOOKUP(A13,'Jan–Apr 2026 Summary'!B:B,'Jan–Apr 2026 Summary'!G:G) -> 152.38966 | F13: =D13-E13 -> -2.7353514e-06
A14: 81600 | B14: Utilities expense | C14: 공과금 | D14: 494.38701 | E14: =_xlfn.XLOOKUP(A14,'Jan–Apr 2026 Summary'!B:B,'Jan–Apr 2026 Summary'!G:G)-683.47+298.86 -> 326.76495 | F14: =D14-E14 -> 167.62206
A15: 81601 | B15: Staff housing utilities | C15: 임직원 숙소 공과금 | D15: 0 | E15: 0 | F15: =D15-E15 -> 0
A16: 81900 | B16: Short‑term lease / rent expense | C16: 단기 임차료 / 임대료 | D16: 7705.2823 | E16: =_xlfn.XLOOKUP(A16,'Jan–Apr 2026 Summary'!B:B,'Jan–Apr 2026 Summary'!G:G) -> 7681.7131 | F16: =D16-E16 -> 23.569219
A17: 81902 | B17: Equipment rental expense | C17: 장비 임차료 | D17: 34.455864 | E17: =_xlfn.XLOOKUP(A17,'Jan–Apr 2026 Summary'!B:B,'Jan–Apr 2026 Summary'!G:G) -> 34.455865 | F17: =D17-E17 -> -6.1847306e-07
A18: 82100 | B18: Insurance expense | C18: 보험료 | D18: 359.81746 | E18: =_xlfn.XLOOKUP(A18,'Jan–Apr 2026 Summary'!B:B,'Jan–Apr 2026 Summary'!G:G) -> 358.71684 | F18: =D18-E18 -> 1.1006237
A19: 82200 | B19: Vehicle maintenance expense | C19: 차량 유지비 | D19: 3532.5045 | E19: =_xlfn.XLOOKUP(A19,'Jan–Apr 2026 Summary'!B:B,'Jan–Apr 2026 Summary'!G:G) -> 3532.5046 | F19: =D19-E19 -> -6.3407461e-05
A20: 82300 | B20: Cleaning & Maintainence | C20: 청소 및 시설유지비 | D20: 683.47003 | E20: 683.47 | F20: =D20-E20 -> 3.0031797e-05
A21: 82400 | B21: Freight and logistics expense | C21: 운송 및 물류비 | D21: 361.88772 | E21: =_xlfn.XLOOKUP(A21,'Jan–Apr 2026 Summary'!B:B,'Jan–Apr 2026 Summary'!G:G) -> 361.88772 | F21: =D21-E21 -> -6.4957825e-06
A22: 83000 | B22: Office supplies expense | C22: 사무용품비 | D22: 109.88679 | E22: =_xlfn.XLOOKUP(A22,'Jan–Apr 2026 Summary'!B:B,'Jan–Apr 2026 Summary'!G:G) -> 109.88679 | F22: =D22-E22 -> -1.972437e-06
A23: 83100 | B23: Professional fees | C23: 외주용역비 / 전문가 수수료 | D23: 7799.5612 | E23: =_xlfn.XLOOKUP(A23,'Jan–Apr 2026 Summary'!B:B,'Jan–Apr 2026 Summary'!G:G) -> 7799.5613 | F23: =D23-E23 -> -0.00013999993
A24: 83102 | B24: Bank charges | C24: 은행수수료 | D24: 2.4706899 | E24: =_xlfn.XLOOKUP(A24,'Jan–Apr 2026 Summary'!B:B,'Jan–Apr 2026 Summary'!G:G) -> 2.4853456 | F24: =D24-E24 -> -0.01465572
A25: 83101 | B25: Staff secondment cost | C25: 파견 인력 비용 | D25: 68528.236 | E25: =_xlfn.XLOOKUP(A25,'Jan–Apr 2026 Summary'!B:B,'Jan–Apr 2026 Summary'!G:G) -> 68528.238 | F25: =D25-E25 -> -0.0012300625
A26: 83103 | B26: Dues & Subscriptions | C26: 회비 및 구독료 | D26: 27.614951 | E26: 27.614951 | F26: =D26-E26 -> -4.9568058e-07
B27: Total Cost | D27: =SUM(D7:D26) -> 174008.7 | E27: =SUM(E7:E26) -> 174594.81 | F27: =SUM(F7:F26) -> -586.11438
B28: Add Markup 6% | D28: =D27*0.06 -> 10440.522 | E28: =E27*0.06 -> 10475.689 | F28: =D28-E28 -> -35.166863
B30: Revenue / Cost recoveries | D30: =D27+D28 -> 184449.22 | E30: =E27+E28 -> 185070.5 | F30: =D30-E30 -> -621.28124
D31: =$D$4*D30 -> 2.6717298e+08 | E31: =$D$4*E30 -> 2.680729e+08
A33: Co Code | B33: Reference | C33: Doc. Type | D33: Document Date | E33: Posting Date | F33: Posting Period | G33: Doc. HeaderText | H33: Reversal Date | I33: Doc Currency | J33: Pstky | K33: Local Account | L33: Pymt Term | M33: Amount In Doc Curr(USD) | N33: Amount In Local Curr(KRW) | O33: Amt in 2nd Curr | P33: Cost Center | Q33: Profit Center | R33: Value Date | S33: Assignment | T33: Line Item Text | U33: Ref Key 1 | V33: Ref Key 2 | W33: Ref Key 3
A34: 4 CHAR | B34: 16 CHAR | C34: 2 CHAR | D34: 31.12.2023 | E34: 31.12.2023 | F34: 2 CHAR | G34: 25 CHAR | H34: - | I34: 5 CHAR | J34: 2 CHAR | P34: 10 CHAR | Q34: 10 CHAR | R34: - | S34: 18 CHAR | T34: 50 CHAR | U34: 12 CHAR | V34: 12 CHAR | W34: 20 CHAR
A35: 1 | B35: Qatar Energy Seoul Office | C35: SA | D35: 2.10.2026 | E35: 2.10.2026 | G35: February Closing_2026 | I35: USD | K35: 10303 | L35: HANA BANK KR KRW CLRG CURRENT (56404) | M35: -2438.7568 | N35: -3558700 | R35: 2.10.2026 | T35: Health Insurance &Long-Term Care Insurance (Jan 2026)(HANA BANK KRW(56404)) | U35: PV2602011
B36: Qatar Energy Seoul Office | C36: SA | D36: 2.10.2026 | E36: 2.10.2026 | G36: February Closing_2026 | I36: USD | K36: 25400 | L36: Withholding Payable | M36: 1080.973 | N36: 1572710 | R36: 2.10.2026 | T36: Health Insurance (Jan 2026)(Health Insurance) | U36: PV2602011
B37: Qatar Energy Seoul Office | C37: SA | D37: 2.10.2026 | E37: 2.10.2026 | G37: February Closing_2026 | I37: USD | K37: 81101 | L37: Social Insurance | M37: 1085.7577 | N37: 1572710 | R37: 2.10.2026 | T37: Health Insurance (Jan 2026)(Health Insurance) Employer contribution | U37: PV2602011
B38: Qatar Energy Seoul Office | C38: SA | D38: 2.10.2026 | E38: 2.10.2026 | G38: February Closing_2026 | I38: USD | K38: 25400 | L38: Withholding Payable | M38: 142.03017 | N38: 206640 | R38: 2.10.2026 | T38: Long-Term Care Insurance (Jan 2026)(Long-Term Care Insurance) | U38: PV2602011
B39: Qatar Energy Seoul Office | C39: SA | D39: 2.10.2026 | E39: 2.10.2026 | G39: February Closing_2026 | I39: USD | K39: 81101 | L39: Social Insurance | M39: 142.65884 | N39: 206640 | R39: 2.10.2026 | T39: Long-Term Care Insurance (Jan 2026)(Long-Term Care Insurance) Employer contribution | U39: PV2602011
B40: Qatar Energy Seoul Office | C40: SA | D40: 2.10.2026 | E40: 2.10.2026 | G40: February Closing_2026 | I40: USD | K40: 83900 | L40: FX Gain/Loss | M40: -12.662918 | N40: -12.662918 | R40: 2.10.2026 | T40: FX Gain on Withholding Payable | U40: PV2602011
B41: Qatar Energy Seoul Office | C41: SA | D41: 2.10.2026 | E41: 2.10.2026 | G41: February Closing_2026 | I41: USD | K41: 10303 | L41: HANA BANK KR KRW CLRG CURRENT (56404) | M41: -1566.3498 | N41: -2285660 | R41: 2.10.2026 | T41: National Pension (Jan 2026)(HANA BANK KRW(56404)) | U41: PV2602012
B42: Qatar Energy Seoul Office | C42: SA | D42: 2.10.2026 | E42: 2.10.2026 | G42: February Closing_2026 | I42: USD | K42: 25400 | L42: Withholding Payable | M42: 785.50299 | N42: 1142830 | R42: 2.10.2026 | T42: National Pension (Jan 2026)(National Pension) | U42: PV2602012
B43: Qatar Energy Seoul Office | C43: SA | D43: 2.10.2026 | E43: 2.10.2026 | G43: February Closing_2026 | I43: USD | K43: 81101 | L43: Social Insurance | M43: 788.97985 | N43: 1142830 | R43: 2.10.2026 | T43: National Pension (Jan 2026)(National Pension) | U43: PV2602012
...

Sheet Revenue Markup Working March
A1: QATAR ENERGY Seoul, LLC
A2: Income : cost plus mark up 6%
A3: As at 31 March 2026
E5: 1488.4736
A6: Account Code | B6: Description | D6: YTD -Amounts USD | E6: PL
A7: 80200 | B7: Salaries and wages expense | C7: 급여 및 임금 | D7: 30152.098 | E7: =_xlfn.XLOOKUP(A7,'Jan–Apr 2026 Summary'!B:B,'Jan–Apr 2026 Summary'!I:I) -> 30152.097 | F7: =D7-E7 -> 0.0006482259
A8: 81110 | B8: Bonus | C8: 상여금 | D8: 0 | E8: 0 | F8: =D8-E8 -> 0
A9: 81100 | B9: Employee benefits expense | C9: 종업원 복리후생비 | D9: 3493.7001 | E9: =_xlfn.XLOOKUP(A9,'Jan–Apr 2026 Summary'!B:B,'Jan–Apr 2026 Summary'!I:I) -> 3390.386 | F9: =D9-E9 -> 103.3141
A10: 81101 | B10: Social security expense | C10: 사회보험료 | D10: 2810.369 | E10: =_xlfn.XLOOKUP(A10,'Jan–Apr 2026 Summary'!B:B,'Jan–Apr 2026 Summary'!I:I) -> 2810.369 | F10: =D10-E10 -> 6.0418814e-05
A11: 81200 | B11: Travel expense | C11: 출장비 | D11: 0 | E11: =_xlfn.XLOOKUP(A11,'Jan–Apr 2026 Summary'!B:B,'Jan–Apr 2026 Summary'!I:I) -> 0 | F11: =D11-E11 -> 0
A12: 81300 | B12: Entertainment expense | C12: 접대비 | D12: 0 | E12: =_xlfn.XLOOKUP(A12,'Jan–Apr 2026 Summary'!B:B,'Jan–Apr 2026 Summary'!I:I) -> 0 | F12: =D12-E12 -> 0
A13: 81400 | B13: Communication expense | C13: 통신비 | D13: 107.35226 | E13: =_xlfn.XLOOKUP(A13,'Jan–Apr 2026 Summary'!B:B,'Jan–Apr 2026 Summary'!I:I) -> 107.35763 | F13: =D13-E13 -> -0.0053723255
A14: 81600 | B14: Utilities expense | C14: 공과금 | D14: 446.97751 | E14: =_xlfn.XLOOKUP(A14,'Jan–Apr 2026 Summary'!B:B,'Jan–Apr 2026 Summary'!I:I)-846.5+419.66 -> 445.94673 | F14: =D14-E14 -> 1.0307874
A15: 81601 | B15: Staff housing utilities | C15: 임직원 숙소 공과금 | D15: 0 | E15: 0 | F15: =D15-E15 -> 0
A16: 81900 | B16: Short‑term lease / rent expense | C16: 단기 임차료 / 임대료 | D16: 25100.266 | E16: =_xlfn.XLOOKUP(A16,'Jan–Apr 2026 Summary'!B:B,'Jan–Apr 2026 Summary'!I:I) -> 24351.315 | F16: =D16-E16 -> 748.95058
A17: 81902 | B17: Equipment rental expense | C17: 장비 임차료 | D17: 33.530323 | E17: =_xlfn.XLOOKUP(A17,'Jan–Apr 2026 Summary'!B:B,'Jan–Apr 2026 Summary'!I:I) -> 33.530323 | F17: =D17-E17 -> 7.2085279e-07
A18: 82100 | B18: Insurance expense | C18: 보험료 | D18: 358.31704 | E18: =_xlfn.XLOOKUP(A18,'Jan–Apr 2026 Summary'!B:B,'Jan–Apr 2026 Summary'!I:I) -> 347.56948 | F18: =D18-E18 -> 10.747553
A19: 82200 | B19: Vehicle maintenance expense | C19: 차량 유지비 | D19: 3408.1895 | E19: =_xlfn.XLOOKUP(A19,'Jan–Apr 2026 Summary'!B:B,'Jan–Apr 2026 Summary'!I:I) -> 3408.1894 | F19: =D19-E19 -> 7.3271078e-05
A20: 82300 | B20: Cleaning & Maintainence | C20: 청소 및 시설유지비 | D20: 846.50479 | E20: 846.5 | F20: =D20-E20 -> 0.0047865734
A21: 85000 | B21: Income Tax Expense | C21: 법인세 비용 | D21: 6668.953 | E21: 6668.1532 | F21: =D21-E21 -> 0.79979395
A22: 82400 | B22: Freight and logistics expense | C22: 운송 및 물류비 | D22: 0 | E22: =_xlfn.XLOOKUP(A22,'Jan–Apr 2026 Summary'!B:B,'Jan–Apr 2026 Summary'!I:I) -> 0 | F22: =D22-E22 -> 0
A23: 83000 | B23: Office supplies expense | C23: 사무용품비 | D23: 65.939849 | E23: =_xlfn.XLOOKUP(A23,'Jan–Apr 2026 Summary'!B:B,'Jan–Apr 2026 Summary'!I:I) -> 63.823772 | F23: =D23-E23 -> 2.1160766
A24: 83100 | B24: Professional fees | C24: 외주용역비 / 전문가 수수료 | D24: 8462.7072 | E24: =_xlfn.XLOOKUP(A24,'Jan–Apr 2026 Summary'!B:B,'Jan–Apr 2026 Summary'!I:I) -> 8462.707 | F24: =D24-E24 -> 0.0001819358
A25: 83102 | B25: Bank charges | C25: 은행수수료 | D25: 4.2997069 | E25: =_xlfn.XLOOKUP(A25,'Jan–Apr 2026 Summary'!B:B,'Jan–Apr 2026 Summary'!I:I) -> 4.2997068 | F25: =D25-E25 -> 9.2437393e-08
A26: 83101 | B26: Staff secondment cost | C26: 파견 인력 비용 | D26: 62073.317 | E26: =_xlfn.XLOOKUP(A26,'Jan–Apr 2026 Summary'!B:B,'Jan–Apr 2026 Summary'!I:I) -> 62073.316 | F26: =D26-E26 -> 0.0013344853
A27: 83103 | B27: Dues & Subscriptions | C27: 회비 및 구독료 | D27: 26.873168 | E27: 26.87 | F27: =D27-E27 -> 0.0031678277
B28: Total Cost | D28: =SUM(D7:D27) -> 144059.39 | E28: =SUM(E7:E27) -> 143192.43 | F28: =D28-E28 -> 866.96378
B29: Add Markup 6% | D29: =D28*0.06 -> 8643.5637 | E29: =E28*0.06 -> 8591.5459 | F29: =D29-E29 -> 52.017827
B31: Revenue / Cost recoveries | D31: =D28+D29 -> 152702.96 | E31: =E28+E29 -> 151783.98 | F31: =D31-E31 -> 918.98161
D32: =D31*$E$5 -> 2.2729432e+08 | E32: =E31*$E$5 -> 2.2592644e+08
A34: Co Code | B34: Reference | C34: Doc. Type | D34: Document Date | E34: Posting Date | F34: Posting Period | G34: Doc. HeaderText | H34: Reversal Date | I34: Doc Currency | J34: Pstky | K34: Local Account | L34: Pymt Term | M34: Amount In Doc Curr(USD) | N34: Amount In Local Curr(KRW) | O34: Amt in 2nd Curr | P34: Cost Center | Q34: Profit Center | R34: Value Date | S34: Assignment | T34: Line Item Text | U34: Ref Key 1 | V34: Ref Key 2 | W34: Ref Key 3
A35: 4 CHAR | B35: 16 CHAR | C35: 2 CHAR | D35: 31.12.2023 | E35: 31.12.2023 | F35: 2 CHAR | G35: 25 CHAR | H35: - | I35: 5 CHAR | J35: 2 CHAR | P35: 10 CHAR | Q35: 10 CHAR | R35: - | S35: 18 CHAR | T35: 50 CHAR | U35: 12 CHAR | V35: 12 CHAR | W35: 20 CHAR
A36: 1 | B36: Qatar Energy Seoul Office | C36: SA | D36: 3.30.2026 | E36: 3.30.2026 | G36: March Closing_2026 | I36: USD | K36: 13300 | L36: Prepaid expenses | M36: -3462.46 | N36: -5000000 | R36: 3.30.2026 | T36: Employee Housing (Mar 2026)(Michelan Apartment(Samseong-d)) | U36: JV2603020
B37: Qatar Energy Seoul Office | C37: SA | D37: 3.30.2026 | E37: 3.30.2026 | G37: March Closing_2026 | I37: USD | K37: 81100 | L37: Employee benefits expense | M37: 3462.46 | N37: 5000000 | R37: 3.30.2026 | T37: Employee Housing (Mar 2026)(Michelan Apartment(Samseong-d)) | U37: JV2603020
A38: 2 | B38: Qatar Energy Seoul Office | C38: SA | D38: 2.28.2026 | E38: 2.28.2026 | G38: March Closing_2026 | I38: USD | K38: 83000 | L38: Office supplies expense | M38: 55.862411 | N38: 80000 | R38: 2.28.2026 | T38: Office supplies(Kinskin Korea Co., Ltd.) | U38: JV2603001
B39: Qatar Energy Seoul Office | C39: SA | D39: 2.28.2026 | E39: 2.28.2026 | G39: March Closing_2026 | I39: USD | K39: 13300 | L39: Prepaid expenses | M39: -55.862411 | N39: -80000 | R39: 2.28.2026 | T39: Kinskin Korea Co., Ltd.(Kinskin Korea Co., Ltd.) | U39: JV2603001
B40: Qatar Energy Seoul Office | C40: SA | D40: 3.3.2026 | E40: 3.3.2026 | G40: March Closing_2026 | I40: USD | K40: 10302 | L40: HANA BANK KR KRW CLRG CURRENT (24104) | M40: -10.077438 | N40: -15000 | R40: 3.3.2026 | T40: (주)베스트문구(HANA BANK KRW(24104)) | U40: PV2603001
B41: Qatar Energy Seoul Office | C41: SA | D41: 3.3.2026 | E41: 3.3.2026 | G41: March Closing_2026 | I41: USD | K41: 83000 | L41: Office supplies expense | M41: 10.077438 | N41: 15000 | R41: 3.3.2026 | T41: Office supplies | U41: PV2603001
A42: 3 | B42: Qatar Energy Seoul Office | C42: SA | D42: 3.30.2026 | E42: 3.30.2026 | G42: March Closing_2026 | I42: USD | K42: 13600 | L42: Prepaid income taxes | M42: -24.438043 | N42: -35290 | R42: 3.30.2026 | T42: CIT2025(Yeoksam Tax Office) | U42: JV2603018
B43: Qatar Energy Seoul Office | C43: SA | D43: 3.30.2026 | E43: 3.30.2026 | G43: March Closing_2026 | I43: USD | K43: 13600 | L43: Prepaid income taxes | M43: -2.3613977 | N43: -3410 | R43: 3.30.2026 | T43: LCIT2025(Gangnam-gu Office) | U43: JV2603018
...

Sheet Revenue Markup Working April
A1: QATAR ENERGY Seoul, LLC
A2: Income : cost plus mark up 6%
A3: As at 30 April 2026
A5: Pertains to End of Service benefit for Mr. Song Huisok(81800) | D5: 1485.7594
A6: Account Code | B6: Description | D6: YTD -Amounts USD | E6: PL
A7: 80200 | B7: Salaries and wages expense | C7: 급여 및 임금 | D7: 56896.7 | E7: =_xlfn.XLOOKUP(A7,'Jan–Apr 2026 Summary'!B:B,'Jan–Apr 2026 Summary'!K:K) -> 56896.698 | F7: =D7-E7 -> 0.0015317877
A8: 81110 | B8: Bonus | C8: 상여금 | D8: 0 | E8: 0 | F8: =D8-E8 -> 0
A9: 81100 | B9: Employee benefits expense | C9: 종업원 복리후생비 | D9: 5322.7775 | E9: =_xlfn.XLOOKUP(A9,'Jan–Apr 2026 Summary'!B:B,'Jan–Apr 2026 Summary'!K:K) -> 5223.0469 | F9: =D9-E9 -> 99.730614
A10: 81800 | B10: Retirement Benefits | C10: 퇴직급여 | D10: 218972.68 | E10: 218971.81 | F10: =D10-E10 -> 0.86942671 | G10: *KRW 325,339,425
A11: 81101 | B11: Social security expense | C11: 사회보험료 | D11: 2614.9913 | E11: =_xlfn.XLOOKUP(A11,'Jan–Apr 2026 Summary'!B:B,'Jan–Apr 2026 Summary'!K:K) -> 2600.8451 | F11: =D11-E11 -> 14.146217
A12: 81200 | B12: Travel expense | C12: 출장비 | D12: 681.84662 | E12: 681.85 | F12: =D12-E12 -> -0.0033784852
A13: 81300 | B13: Entertainment expense | C13: 접대비 | D13: 0 | E13: =_xlfn.XLOOKUP(A13,'Jan–Apr 2026 Summary'!B:B,'Jan–Apr 2026 Summary'!K:K) -> 0 | F13: =D13-E13 -> 0
A14: 81400 | B14: Communication expense | C14: 통신비 | D14: 111.81151 | E14: =_xlfn.XLOOKUP(A14,'Jan–Apr 2026 Summary'!B:B,'Jan–Apr 2026 Summary'!K:K) -> 111.81151 | F14: =D14-E14 -> 3.0102185e-06
A15: 81600 | B15: Utilities expense | C15: 공과금 | D15: 45.954162 | E15: 45.95 | F15: =D15-E15 -> 0.004162117
A16: 81601 | B16: Staff housing utilities | C16: 임직원 숙소 공과금 | D16: 310.4877 | E16: =_xlfn.XLOOKUP(A16,'Jan–Apr 2026 Summary'!B:B,'Jan–Apr 2026 Summary'!K:K)-19.31 -> 310.54085 | F16: =D16-E16 -> -0.053153671
A17: 81900 | B17: Short‑term lease / rent expense | C17: 단기 임차료 / 임대료 | D17: 25100.266 | E17: =_xlfn.XLOOKUP(A17,'Jan–Apr 2026 Summary'!B:B,'Jan–Apr 2026 Summary'!K:K) -> 24395.801 | F17: =D17-E17 -> 704.46536
A18: 81902 | B18: Equipment rental expense | C18: 장비 임차료 | D18: 33.591577 | E18: =_xlfn.XLOOKUP(A18,'Jan–Apr 2026 Summary'!B:B,'Jan–Apr 2026 Summary'!K:K) -> 33.591576 | F18: =D18-E18 -> 9.0436114e-07
A19: 82100 | B19: Insurance expense | C19: 보험료 | D19: 358.31704 | E19: =_xlfn.XLOOKUP(A19,'Jan–Apr 2026 Summary'!B:B,'Jan–Apr 2026 Summary'!K:K) -> 348.20443 | F19: =D19-E19 -> 10.11261
A20: 82200 | B20: Vehicle maintenance expense | C20: 차량 유지비 | D20: 3606.9098 | E20: =_xlfn.XLOOKUP(A20,'Jan–Apr 2026 Summary'!B:B,'Jan–Apr 2026 Summary'!K:K) -> 3606.9097 | F20: =D20-E20 -> 9.7106161e-05
A21: 82300 | B21: Cleaning & Maintainence | C21: 청소 및 시설유지비 | D21: 888.43458 | E21: 888.43 | F21: =D21-E21 -> 0.0045847231
A22: 85000 | B22: Income Tax Expense | C22: 법인세 비용 | D22: 0 | E22: 0 | F22: =D22-E22 -> 0
A23: 82400 | B23: Freight and logistics expense | C23: 운송 및 물류비 | D23: 0 | E23: 0 | F23: =D23-E23 -> 0
A24: 83000 | B24: Office supplies expense | C24: 사무용품비 | D24: 421.6699 | E24: 421.67 | F24: =D24-E24 -> -0.00010050834
A25: 83100 | B25: Professional fees | C25: 외주용역비 / 전문가 수수료 | D25: 11096.413 | E25: 11096.41 | F25: =D25-E25 -> 0.0033518903
A26: 83102 | B26: Bank charges | C26: 은행수수료 | D26: 6.4613424 | E26: =_xlfn.XLOOKUP(A26,'Jan–Apr 2026 Summary'!B:B,'Jan–Apr 2026 Summary'!K:K) -> 6.4613423 | F26: =D26-E26 -> 1.7395394e-07
A27: 83101 | B27: Staff secondment cost | C27: 파견 인력 비용 | D27: 49514.29 | E27: =_xlfn.XLOOKUP(A27,'Jan–Apr 2026 Summary'!B:B,'Jan–Apr 2026 Summary'!K:K) -> 53003.087 | F27: =D27-E27 -> -3488.7972 | G27: *KRW 78,749,835
A28: 83103 | B28: Dues & Subscriptions | C28: 회비 및 구독료 | D28: 127.88074 | E28: 127.88 | F28: =D28-E28 -> 0.00073567983
B29: Total Cost | D29: =SUM(D7:D28) -> 376111.48 | E29: =SUM(E7:E28) -> 378771 | F29: =D29-E29 -> -2659.5151
B30: Add Markup 6% | D30: =D29*0.06 -> 22566.689 | E30: =E29*0.06 -> 22726.26 | F30: =D30-E30 -> -159.57091
B32: Revenue / Cost recoveries | D32: =D29+D30 -> 398678.17 | E32: =E29+E30 -> 401497.26 | F32: =D32-E32 -> -2819.086
D33: =D32*$D$5 -> 5.9233984e+08 | E33: =E32*$D$5 -> 5.9652832e+08
A35: Co Code | B35: Reference | C35: Doc. Type | D35: Document Date | E35: Posting Date | F35: Posting Period | G35: Doc. HeaderText | H35: Reversal Date | I35: Doc Currency | J35: Pstky | K35: Local Account | L35: Pymt Term | M35: Amount In Doc Curr(USD) | N35: Amount In Local Curr(KRW) | O35: Amt in 2nd Curr | P35: Cost Center | Q35: Profit Center | R35: Value Date | S35: Assignment | T35: Line Item Text | U35: Ref Key 1 | V35: Ref Key 2 | W35: Ref Key 3
A36: 4 CHAR | B36: 16 CHAR | C36: 2 CHAR | D36: 31.12.2023 | E36: 31.12.2023 | F36: 2 CHAR | G36: 25 CHAR | H36: - | I36: 5 CHAR | J36: 2 CHAR | P36: 10 CHAR | Q36: 10 CHAR | R36: - | S36: 18 CHAR | T36: 50 CHAR | U36: 12 CHAR | V36: 12 CHAR | W36: 20 CHAR
A37: 1 | B37: Qatar Energy Seoul Office | C37: SA | D37: 4.30.2026 | E37: 4.30.2026 | G37: April Closing_2026 | I37: USD | K37: 81800 | L37: Retirement Benefits | M37: 218972.68 | N37: 325340708 | R37: 4.30.2026 | T37: Business Certificate Fee(((주)하나은행) | U37: JV2604007
A38: 2 | B38: Qatar Energy Seoul Office | C38: SA | D38: 4.10.2026 | E38: 4.10.2026 | G38: April Closing_2026 | I38: USD | K38: 81101 | L38: Social Insurance | M38: 1148.5775 | N38: 1694870 | R38: 4.10.2026 | T38: Local Income Tax(Mar 2026)(Gangnam-gu Office) | U38: PV26040012
B39: Qatar Energy Seoul Office | C39: SA | D39: 4.10.2026 | E39: 4.10.2026 | G39: April Closing_2026 | I39: USD | K39: 81101 | L39: Social Insurance | M39: 150.93262 | N39: 222720 | R39: 4.10.2026 | T39: Health Insurance (Mar 2026)(Health Insurance) | U39: PV26040013
B40: Qatar Energy Seoul Office | C40: SA | D40: 4.10.2026 | E40: 4.10.2026 | G40: April Closing_2026 | I40: USD | K40: 81101 | L40: Social Insurance | M40: 774.47165 | N40: 1142830 | R40: 4.10.2026 | T40: FX Loss on Withholding Payable | U40: PV26040013
B41: Qatar Energy Seoul Office | C41: SA | D41: 4.10.2026 | E41: 4.10.2026 | G41: April Closing_2026 | I41: USD | K41: 81101 | L41: Social Insurance | M41: 541.00955 | N41: 803810 | R41: 4.10.2026 | T41: FX Loss on Withholding Payable | U41: PV26040015
A42: 3 | B42: Qatar Energy Seoul Office | C42: SA | D42: 4.30.2026 | E42: 4.30.2026 | G42: April Closing_2026 | I42: USD | K42: 81900 | L42: Rent expense | M42: 7705.2823 | N42: 11126890 | R42: 4.30.2026 | T42: Electricity Charges (Apr 2026)(Gangnam Finance Center Co., Ltd.) | U42: JV2604002
B43: Qatar Energy Seoul Office | C43: SA | D43: 4.30.2026 | E43: 4.30.2026 | G43: April Closing_2026 | I43: USD | K43: 81900 | L43: Rent expense | M43: 17394.984 | N43: 25119400 | R43: 4.30.2026 | T43: Office Maintenance Fee (Apr 2026)(Gangnam Finance Center Co., Ltd.) | U43: JV2604003
...
