Workbook

Sheet CFS Template_2026
B1: Liquidity Item | C1: January | D1: February | E1: March | F1: April | G1: May | H1: June | I1: July | J1: August | K1: September | L1: October | M1: November | N1: December | O1: Accumulated
R2: Please, only include figures in green cells
A3: Operating Activities | O3: =SUM(C3:N3) -> 0
A4: Cash receipts from customers | B4: OA_BLACK_TP | O4: =SUM(C4:N4) -> 0
A5: Cash paid to suppliers | D5: =SUM(D6:D8) -> 0 | O5: =SUM(C5:N5) -> 0
A6: Cash paid for O&M (Operation & maintenace costs) | B6: OA_OM_TP | O6: =SUM(C6:N6) -> 0
A7: Cash paid for leases and Rents | B7: OA_LEASES | D7: =+'2월'!D10 -> 0 | O7: =SUM(C7:N7) -> 0
A8: Cash paid to other suppliers | B8: OA_OTHER_SS_TP | D8: =+'2월'!B2 -> 0 | O8: =SUM(C8:N8) -> 0
A9: Cash paid to personnel | B9: OA_PERSONNEL | D9: ='2월'!B3 -> 0 | O9: =SUM(C9:N9) -> 0 | R9: Include counterparty information in payments / collections with related parties
A10: Other receipts / (payments) relating to operating activities | D10: =D15+D16+D14+D11 -> 644123235 | O10: =SUM(C10:N10) -> 644123235
A11: State and Other Public Entities | D11: =SUM(D12:D13) -> 0 | O11: =SUM(C11:N11) -> 0
A12: VAT | B12: OA_VAT_OUT | O12: =SUM(C12:N12) -> 0
A13: Other Taxes | B13: OA_OTHERTAX_OUT | O13: =SUM(C13:N13) -> 0
A14: Guarantees received / (paid) | B14: OA_GUARANTEES | O14: =SUM(C14:N14) -> 0
A15: Other Municipal and tax Payments | B15: OA_CONCESSIONS | D15: =+'2월'!B4+C14+C16+C11 -> 660324915 | O15: =SUM(C15:N15) -> 660324915
A16: Other receipts / (payments) | B16: OA_OTHERS_OTHERS | D16: =+'2월'!B5 -> -16201680 | O16: =SUM(C16:N16) -> -16201680
A17: Net cash flows from operations | D17: =D4+D5+D9+D10 -> 644123235 | O17: =SUM(C17:N17) -> 644123235
A18: Income tax received (CASH-IN) | B18: OA_INCOMETAX_IN | O18: =SUM(C18:N18) -> 0 | R18: Please include receipts with a positive sign and payments with a negative sign.
A19: Income tax paid (CASH-OUT) | B19: OA_INCOMETAX_OUT | O19: =SUM(C19:N19) -> 0
A20: Net cash flows from operating activities | D20: =D17+D18+D19 -> 644123235 | O20: =SUM(C20:N20) -> 644123235
A21: Investing Activities
A22: Cash receipts relating to: | D22: =SUM(D23:D30) -> 0 | O22: =SUM(C22:N22) -> 0
A23: Changes in cash resulting from perimeter variations (CASH-IN | B23: IA_CHANGESPER_IN | O23: =SUM(C23:N23) -> 0
A24: Financial assets (CASH-IN) / Sale of assets - subsidiaries | B24: IA_FINASSETS_IN | O24: =SUM(C24:N24) -> 0 | R24: Payments related to capitalized costs as fixed assets should be reflected in investment flows (Property, plant and equipment (CASH-OUT).
A25: Property, plant and equipment (CASH-IN) | B25: IA_TANGIBLE_IN | O25: =SUM(C25:N25) -> 0
A26: Intangible assets (CASH-IN) | B26: IA_INTANGIB_IN | O26: =SUM(C26:N26) -> 0
A27: Loans to related parties (CASH-IN) | B27: IA_GRLOANS_IN | O27: =SUM(C27:N27) -> 0
A28: Subsidies for investment | B28: IA_SUBSIDIES | O28: =SUM(C28:N28) -> 0
A29: Interest and similar income | B29: IA_INTEREST_SIM | O29: =SUM(C29:N29) -> 0
A30: Dividends received | B30: IA_DIVIDENDS | O30: =SUM(C30:N30) -> 0
A31: Cash payments relating to: | D31: =SUM(D32:D36) -> 0 | O31: =SUM(C31:N31) -> 0
A32: Financial assets (CASH-OUT) / Acquisition of assets – subsid | B32: IA_FINASSETS_OUT | O32: =SUM(C32:N32) -> 0
A33: Changes in cash resulting from perimeter variations | B33: IA_CHANGES_PERIM | O33: =SUM(C33:N33) -> 0
A34: Property, plant and equipment (CASH-OUT) | B34: IA_TANGIBLE_OUT | O34: =SUM(C34:N34) -> 0
A35: Intangible assets (CASH-OUT) | B35: IA_INTANGIB_OUT | O35: =SUM(C35:N35) -> 0
A36: Loans to related parties (CASH-OUT) | B36: IA_GRLOANS_OUT | O36: =SUM(C36:N36) -> 0
A37: Net cash flows from investing activities | D37: =D31+D22 -> 0 | O37: =SUM(C37:N37) -> 0
A38: Financing Activities
A39: Cash receipts relating to: | D39: =D40+D43+D46+D47+D48+D49+D50 -> 0 | O39: =SUM(C39:N39) -> 0
A40: Receipts of loans | D40: =SUM(D41:D42) -> 0 | O40: =SUM(O41:O42) -> 0
...

Sheet 2월
C1: (KRW)
A2: Cash paid to other suppliers | C2: 2024 Cash paid for leases and Rents | F2: Being return of deposit from landlord | G2: 10000000 | I2: 654121727
A3: Cash paid to personnel | C3: Details | D3: December | F3: transfer (Shinhan -> HSBC) | G3: 6202688 | I3: 660324415
A4: Other Municipal and tax Payments | B4: =+H4+H5+H6+H7+H22-G3 -> 660324915 | C4: Monthly room rental fee | F4: Being payment to Green Cross I-Med for healthcare screening fee | H4: 1800000 | I4: 658524415
A5: Other receipts / (payments) | B5: =-G21-G2 -> -16201680 | C5: CAR RENTAL (BMW 520i Iux Lci60)-Deposit (30%) | F5: Monthly IT Maintenance Service fee | H5: 330000 | I5: 658194415
C6: CAR RENTAL FEE | D6: 0 | F6: Being payment of office reinstatement fee to M2 Design | H6: 500000 | I6: 657694415
A7: Loans with the Group (CASH-OUT) | C7: EDPR KR-Office sublease-Deposit | F7: Being payment of management fees to SSG | H7: 657694415
A8: Interest with the Group(CASH-OUT) | C8: EDPR KR-Office sublease-Monthly lease | D8: =+H12 -> 0
C9: Office rent/management fee_March, April, May
A10: Loans with the Group (CASH-IN) | C10: Total | D10: =SUM(D4:D9) -> 0
A12: Interest and similar income
G14: 4656329 | H14: 80031670
G15: 1921204931 | H15: 1277083204
H17: =I13+I22 -> 0 | I17: =+I7+J22 -> 0
G20: 1508 | I20: 1508
F21: VAT refund | G21: 6201680 | I21: 6203188
F22: transfer (Shinhan -> HSBC) | H22: 6203188
G23: 6201680 | H23: 6203188
G24: 6203188 | H24: 6203188

Sheet Leases,Rents
B1: (KRW)
B2: 2023 Cash paid for leases and Rents
B3: Details | C3: January | D3: February | E3: March | F3: April | G3: May | H3: June | I3: July | J3: August | K3: September | L3: October | M3: November | N3: December
B4: Monthly room rental fee
B5: CAR RENTAL (BMW 520i Iux Lci60)-Deposit (30%)
B6: CAR RENTAL FEE | C6: 1430000 | D6: 1430000 | E6: 1430000 | F6: 1430000 | G6: 1430000
B7: EDPR KR-Office sublease-Deposit
B8: EDPR KR-Office sublease-Monthly lease | D8: 15002526 | F8: 12259206 | G8: =#REF!*2 -> #REF!
B9: Office rent/management fee_March, April, May
B10: Total | C10: =SUM(C4:C9) -> 1430000 | D10: =SUM(D4:D9) -> 16432526 | E10: =SUM(E4:E9) -> 1430000 | F10: =SUM(F4:F9) -> 13689206 | G10: =SUM(G4:G9) -> #REF! | H10: =SUM(H4:H9) -> 0 | I10: =SUM(I4:I9) -> 0 | J10: =SUM(J4:J9) -> 0 | ... N10: =SUM(N4:N9) -> 0
C11: =-C10='CFS Template_2026'!C7 -> FALSE

Sheet CFS Template_2022
B1: Liquidity Item | C1: January | D1: February | E1: March | F1: April | G1: May | H1: June | I1: July | J1: August | K1: September | L1: October | M1: November | N1: December | O1: Accumulated
R2: Please, only include figures in green cells
A3: Operating Activities | O3: =SUM(C3:N3) -> 0
A4: Cash receipts from customers | B4: OA_BLACK_TP | O4: =SUM(C4:N4) -> 0
A5: Cash paid to suppliers | C5: =SUM(C6:C8) -> 0 | D5: =SUM(D6:D8) -> -5082500 | E5: =SUM(E6:E8) -> -147782000 | F5: =SUM(F6:F8) -> -5082000 | G5: =SUM(G6:G8) -> -8030000 | H5: =SUM(H6:H8) -> -274436088 | I5: =SUM(I6:I8) -> -51898720 | J5: =SUM(J6:J8) -> -33672065 | ... N5: =SUM(N6:N8) -> -94068796 | O5: =SUM(C5:N5) -> -1136251576
A6: Cash paid for O&M (Operation & maintenace costs) | B6: OA_OM_TP | E6: =-(83600000+38500000) -> -122100000 | G6: -6600000 | H6: -111650000 | I6: =-1650000-20900000 -> -22550000 | K6: -22012066 | O6: =SUM(C6:N6) -> -284912066
A7: Cash paid for leases and Rents | B7: OA_LEASES | D7: -5082500 | E7: =-(19170000+5082000+1430000) -> -25682000 | F7: -5082000 | G7: -1430000 | H7: -162786088 | I7: =-15002526-1430000 -> -16432526 | J7: =-1430000-15002526 -> -16432526 | K7: =-1430000-15002526 -> -16432526 | L7: =-1430000-15002526 -> -16432526 | M7: -1430000 | N7: -46437578 | O7: =SUM(C7:N7) -> -313660270
A8: Cash paid to other suppliers | B8: OA_OTHER_SS_TP | I8: =-5318500-5318500-2279194 -> -12916194 | J8: =-8281799-5318500-1650000-1989240 -> -17239539 | K8: =-15500000+-2178000+-238000+-1039500+-346500+-390884769+-1100000+-13132878+-1650000+-418000+-5318500 -> -431806147 | L8: -30000 | M8: -28056142 | N8: =-(1650000+9500705+5733280+6820280+1650000+1136300+44000+2761000+1697270+1305240+1149223+618220+303910+280000+410790+5318500+7252500) -> -47631218 | O8: =SUM(C8:N8) -> -537679240
A9: Cash paid to personnel | B9: OA_PERSONNEL | J9: =-9363023-78410 -> -9441433 | K9: =-94900 -> -94900 | L9: =-26170920+-43528748 -> -69699668 | M9: -62434194 | N9: =-56257038-10000 -> -56267038 | O9: =SUM(C9:N9) -> -197937233 | R9: Include counterparty information in payments / collections with related parties
A10: Other receipts / (payments) relating to operating activities | C10: =C11+C14+C15+C16 -> 0 | D10: =D11+D14+D15+D16 -> 0 | E10: =E11+E14+E15+E16 -> 0 | F10: =F11+F14+F15+F16 -> 0 | G10: =G11+G14+G15+G16 -> 0 | H10: =H11+H14+H15+H16 -> 0 | I10: =I11+I14+I15+I16 -> -181500 | J10: =J11+J14+J15+J16 -> -2167480 | ... N10: =N11+N14+N15+N16 -> -17420 | O10: =SUM(C10:N10) -> 25353110
A11: State and Other Public Entities | C11: =SUM(C12:C13) -> 0 | D11: =SUM(D12:D13) -> 0 | E11: =SUM(E12:E13) -> 0 | F11: =SUM(F12:F13) -> 0 | G11: =SUM(G12:G13) -> 0 | H11: =SUM(H12:H13) -> 0 | I11: =SUM(I12:I13) -> 0 | J11: =SUM(J12:J13) -> -1071170 | ... N11: =SUM(N12:N13) -> -17420 | O11: =SUM(C11:N11) -> -1088590
A12: VAT | B12: OA_VAT_OUT | O12: =SUM(C12:N12) -> 0
A13: Other Taxes | B13: OA_OTHERTAX_OUT | J13: =-889670-181500 -> -1071170 | N13: -17420 | O13: =SUM(C13:N13) -> -1088590
A14: Guarantees received / (paid) | B14: OA_GUARANTEES | O14: =SUM(C14:N14) -> 0
A15: Other Municipal and tax Payments | B15: OA_CONCESSIONS | I15: -181500 | J15: -1096310 | L15: =-62500 -> -62500 | O15: =SUM(C15:N15) -> -1340310
A16: Other receipts / (payments) | B16: OA_OTHERS_OTHERS | K16: 27812600 | M16: -30590 | O16: =SUM(C16:N16) -> 27782010
A17: Net cash flows from operations | C17: =C10+C9+C5+C4 -> 0 | D17: =D10+D9+D5+D4 -> -5082500 | E17: =E10+E9+E5+E4 -> -147782000 | F17: =F10+F9+F5+F4 -> -5082000 | G17: =G10+G9+G5+G4 -> -8030000 | H17: =H10+H9+H5+H4 -> -274436088 | I17: =I10+I9+I5+I4 -> -52080220 | J17: =J10+J9+J5+J4 -> -45280978 | ... N17: =N10+N9+N5+N4 -> -150353254 | O17: =SUM(C17:N17) -> -1308835699
A18: Income tax received (CASH-IN) | B18: OA_INCOMETAX_IN | O18: =SUM(C18:N18) -> 0 | R18: Please include receipts with a positive sign and payments with a negative sign.
A19: Income tax paid (CASH-OUT) | B19: OA_INCOMETAX_OUT | H19: -1490 | K19: =-16500+-170020+-2608680+-260860 -> -3056060 | L19: =-187050+-5323660+-532350 -> -6043060 | M19: -6633280 | N19: =-(39000+390000+7930340+793000) -> -9152340 | O19: =SUM(C19:N19) -> -24886230
A20: Net cash flows from operating activities | C20: =C17+C18+C19 -> 0 | D20: =D17+D18+D19 -> -5082500 | E20: =E17+E18+E19 -> -147782000 | F20: =F17+F18+F19 -> -5082000 | G20: =G17+G18+G19 -> -8030000 | H20: =H17+H18+H19 -> -274437578 | I20: =I17+I18+I19 -> -52080220 | J20: =J17+J18+J19 -> -45280978 | ... N20: =N17+N18+N19 -> -159505594 | O20: =SUM(C20:N20) -> -1333721929
A21: Investing Activities
A22: Cash receipts relating to: | C22: =SUM(C23:C30) -> 0 | D22: =SUM(D23:D30) -> 0 | E22: =SUM(E23:E30) -> 0 | F22: =SUM(F23:F30) -> 0 | G22: =SUM(G23:G30) -> 0 | H22: =SUM(H23:H30) -> 9676 | I22: =SUM(I23:I30) -> 0 | J22: =SUM(J23:J30) -> 0 | ... N22: =SUM(N23:N30) -> 113166 | O22: =SUM(C22:N22) -> 122842
A23: Changes in cash resulting from perimeter variations (CASH-IN | B23: IA_CHANGESPER_IN | O23: =SUM(C23:N23) -> 0
A24: Financial assets (CASH-IN) / Sale of assets - subsidiaries | B24: IA_FINASSETS_IN | O24: =SUM(C24:N24) -> 0 | R24: Payments related to capitalized costs as fixed assets should be reflected in investment flows (Property, plant and equipment (CASH-OUT).
A25: Property, plant and equipment (CASH-IN) | B25: IA_TANGIBLE_IN | O25: =SUM(C25:N25) -> 0
A26: Intangible assets (CASH-IN) | B26: IA_INTANGIB_IN | O26: =SUM(C26:N26) -> 0
A27: Loans to related parties (CASH-IN) | B27: IA_GRLOANS_IN | O27: =SUM(C27:N27) -> 0
A28: Subsidies for investment | B28: IA_SUBSIDIES | O28: =SUM(C28:N28) -> 0
A29: Interest and similar income | B29: IA_INTEREST_SIM | H29: 9676 | N29: 113166 | O29: =SUM(C29:N29) -> 122842
A30: Dividends received | B30: IA_DIVIDENDS | O30: =SUM(C30:N30) -> 0
A31: Cash payments relating to: | C31: =SUM(C32:C36) -> 0 | D31: =SUM(D32:D36) -> 0 | E31: =SUM(E32:E36) -> 0 | F31: =SUM(F32:F36) -> 0 | G31: =SUM(G32:G36) -> 0 | H31: =SUM(H32:H36) -> 0 | I31: =SUM(I32:I36) -> 0 | J31: =SUM(J32:J36) -> 0 | ... N31: =SUM(N32:N36) -> 0 | O31: =SUM(C31:N31) -> -12359896
A32: Financial assets (CASH-OUT) / Acquisition of assets – subsid | B32: IA_FINASSETS_OUT | K32: =-5794740+-4020156 -> -9814896 | O32: =SUM(C32:N32) -> -9814896
A33: Changes in cash resulting from perimeter variations | B33: IA_CHANGES_PERIM | O33: =SUM(C33:N33) -> 0
A34: Property, plant and equipment (CASH-OUT) | B34: IA_TANGIBLE_OUT | K34: -1500000 | L34: -1045000 | O34: =SUM(C34:N34) -> -2545000
A35: Intangible assets (CASH-OUT) | B35: IA_INTANGIB_OUT | O35: =SUM(C35:N35) -> 0
A36: Loans to related parties (CASH-OUT) | B36: IA_GRLOANS_OUT | O36: =SUM(C36:N36) -> 0
A37: Net cash flows from investing activities | C37: =C31+C22 -> 0 | D37: =D31+D22 -> 0 | E37: =E31+E22 -> 0 | F37: =F31+F22 -> 0 | G37: =G31+G22 -> 0 | H37: =H31+H22 -> 9676 | I37: =I31+I22 -> 0 | J37: =J31+J22 -> 0 | ... N37: =N31+N22 -> 113166 | O37: =SUM(C37:N37) -> -12237054
A38: Financing Activities
A39: Cash receipts relating to: | C39: =C40+C43+C46+C47+C48+C49+C50 -> 100000000 | D39: =D40+D43+D46+D47+D48+D49+D50 -> 0 | E39: =E40+E43+E46+E47+E48+E49+E50 -> 200000000 | F39: =F40+F43+F46+F47+F48+F49+F50 -> 0 | G39: =G40+G43+G46+G47+G48+G49+G50 -> 0 | H39: =H40+H43+H46+H47+H48+H49+H50 -> 423000000 | I39: =I40+I43+I46+I47+I48+I49+I50 -> 0 | J39: =J40+J43+J46+J47+J48+J49+J50 -> 0 | ... N39: =N40+N43+N46+N47+N48+N49+N50 -> -10231350 | O39: =SUM(C39:N39) -> 1621374180
A40: Receipts of loans | C40: =SUM(C41:C42) -> 0 | D40: =SUM(D41:D42) -> 0 | E40: =SUM(E41:E42) -> 200000000 | F40: =SUM(F41:F42) -> 0 | G40: =SUM(G41:G42) -> 0 | H40: =SUM(H41:H42) -> 423000000 | I40: =SUM(I41:I42) -> 0 | J40: =SUM(J41:J42) -> 0 | ... O40: =SUM(O41:O42) -> 1533000000
...

Sheet Leases,Rents_2022
B1: (KRW)
B2: Cash paid for leases and Rents
B3: Details | C3: January | D3: February | E3: March | F3: April | G3: May | H3: June | I3: July | J3: August | K3: September | L3: October | M3: November | N3: December
B4: Monthly room rental fee | D4: 5082500 | E4: 5082000 | F4: 5082000 | H4: 0
B5: CAR RENTAL (BMW 520i Iux Lci60)-Deposit (30%) | E5: 19170000
B6: CAR RENTAL FEE | E6: 1430000 | G6: 1430000 | H6: 1430000 | I6: 1430000 | J6: 1430000 | K6: 1430000 | L6: 1430000 | M6: 1430000 | N6: =1430000+40630 -> 1470630
B7: EDPR KR-Office sublease-Deposit | H7: 111013400
B8: EDPR KR-Office sublease-Monthly lease | H8: 15002526 | I8: 15002526 | J8: 15002526 | K8: 15002526 | L8: 15002526 | N8: =15002526*3 -> 45007578
B9: Office rent/management fee_March, April, May | H9: 35340162
B10: Total | D10: =SUM(D4:D9) -> 5082500 | E10: =SUM(E4:E9) -> 25682000 | F10: =SUM(F4:F9) -> 5082000 | G10: =SUM(G4:G9) -> 1430000 | H10: =SUM(H4:H9) -> 162786088 | I10: =SUM(I4:I9) -> 16432526 | J10: =SUM(J4:J9) -> 16432526 | K10: =SUM(K4:K9) -> 16432526 | ... N10: =SUM(N4:N9) -> 46478208
D11: =-D10='CFS Template_2026'!D7 -> FALSE | E11: =-E10='CFS Template_2026'!E7 -> FALSE | F11: =-F10='CFS Template_2026'!F7 -> FALSE | G11: =-G10='CFS Template_2026'!G7 -> FALSE | H11: =-H10='CFS Template_2026'!H7 -> FALSE | I11: =-I10='CFS Template_2026'!I7 -> FALSE | J11: =-J10='CFS Template_2026'!J7 -> FALSE | K11: =-K10='CFS Template_2026'!K7 -> FALSE | L11: =-L10='CFS Template_2026'!L7 -> FALSE | M11: =M10=-'CFS Template_2026'!M7 -> FALSE | N11: =N10=-'CFS Template_2026'!N7 -> FALSE
